Workbook
Name CODONG: '[1]01-15'!$B$3:$F$33

Sheet SGP
B1: BẢNG CHẤM CÔNG NHÂN VIÊN THÁNG 10/2019 | AL1: - Những cột có dấu (*) là bắt buộc người chấm công phải nhập dữ liệu (nếu có)
B2: ( Từ Ngày 01/10/2019 đến 31/10/2019 )
C3: Bãi xe: SGP | AL3: Phần nhập của Quản lý Bãi xe | AP3: Phần nhập của Phòng HCNS
AL4: (*) | AM4: (*) | AN4: (*) | AO4: (*)
D5: 1 | E5: 2 | F5: 3 | G5: 4 | H5: 5 | I5: 6 | J5: 7 | K5: 8 | L5: 9 | M5: 10 | N5: 11 | O5: 12 | P5: 13 | Q5: 14 | R5: 15 | S5: 16 | T5: 17 | U5: 18 | V5: 19 | W5: 20 | X5: 21 | Y5: 22 | Z5: 23 | AA5: 24 | AB5: 25 | AC5: 26 | AD5: 27 | AE5: 28 | AF5: 29 | AG5: 30 | AH5: 31 | AI5: 32 | AJ5: 33 | AK5: 34 | AL5: 35 | AM5: 36 | AN5: 37 | AO5: 38 | AP5: 39 | AQ5: 40 | AR5: 41 | AS5: 42 | AT5: 43 | AU5: 44 | AV5: 45 | AW5: 46 | AX5: 47
C6: THÁNG | D6: 9
C7: NĂM | D7: 2026
B8: Phần in ra cho Nhân viên ký xác nhận
B9: STT | C9: HỌ VÀ TÊN | D9: Thứ | E9: =TEXT(E10,"ddd") -> T3 | F9: =TEXT(F10,"ddd") -> T4 | G9: =TEXT(G10,"ddd") -> T5 | H9: =TEXT(H10,"ddd") -> T6 | I9: =TEXT(I10,"ddd") -> T7 | J9: =TEXT(J10,"ddd") -> CN | K9: =TEXT(K10,"ddd") -> T2 | L9: =TEXT(L10,"ddd") -> T3 | ... AI9: =TEXT(AI10,"ddd") | AK9: NV Ký Xác nhận | AL9: Thông tin Tham chiếu | AP9: Giờ công (h) | AW9: Đánh giá
D10: MSNV | E10: =DATE(D7,D6,1) -> 46266 | F10: =IFERROR(IF(E10+1<=EOMONTH(E10,0),E10+1,""),"") -> 46267 | G10: =IFERROR(IF(F10+1<=EOMONTH(F10,0),F10+1,""),"") -> 46268 | H10: =IFERROR(IF(G10+1<=EOMONTH(G10,0),G10+1,""),"") -> 46269 | I10: =IFERROR(IF(H10+1<=EOMONTH(H10,0),H10+1,""),"") -> 46270 | J10: =IFERROR(IF(I10+1<=EOMONTH(I10,0),I10+1,""),"") -> 46271 | K10: =IFERROR(IF(J10+1<=EOMONTH(J10,0),J10+1,""),"") -> 46272 | L10: =IFERROR(IF(K10+1<=EOMONTH(K10,0),K10+1,""),"") -> 46273 | M10: =IFERROR(IF(L10+1<=EOMONTH(L10,0),L10+1,""),"") -> 46274 | ... AI10: =IFERROR(IF(AH10+1<=EOMONTH(AH10,0),AH10+1,""),"") | AJ10: Tổng giờ Công | AL10: Đối tượng / Chức vụ | AM10: Ghi chú | AN10: Bãi xe (chỉ ghi khi có NV đến hỗ trợ) | AO10: Ca làm việc | AP10: Tổng số ngày Làm việc trong tháng | AQ10: Giờ công thường 1.0 | AR10: Số ngày tăng ca ngày nghỉ | AS10: Tăng ca ngày 1.3 | AT10: Tăng ca giờ 1.5 | AU10: Tăng ca Lễ 2.0 | AV10: Tăng ca tết 3.0 | AW10: Bãi xe Đánh giá | AX10: P. Nhân sự đánh giá | AY10: công đt
B11: A | C11: Ca Ngày | D11: MSNV | AL11: 4 CÔNG, 5 VỈA HÈ
C12: LÊ THANH BÌNH | D12: KV895 | E12: OFF | F12: OFF | G12: 9 | H12: 9 | I12: 4 | J12: OFF | K12: 9 | L12: 9 | M12: 9 | N12: 9 | O12: 9 | P12: 4 | Q12: OFF | R12: 9 | S12: 9 | T12: 9 | U12: 9 | V12: 9 | W12: 4 | X12: OFF | Y12: 9 | Z12: 9 | AA12: 9 | AB12: 9 | AC12: 9 | AD12: 4 | AE12: OFF | AF12: 9 | AG12: 9 | AH12: 9 | AL12: TĐH | AM12: TĐH
B13: 1 | C13: ĐINH THỊ MỘNG TRINH | D13: KV05390 | E13: 12 | F13: 12 | G13: 12 | H13: 12 | I13: 12 | J13: 12 | K13: 16 | L13: 12 | M13: 16 | N13: 12 | O13: 16 | P13: 16 | Q13: 12 | R13: 16 | S13: 12 | T13: 12 | U13: OFF | V13: OFF | W13: 12 | X13: 12 | Y13: 12 | Z13: 12 | AA13: 12 | AB13: 12 | AC13: 12 | AD13: 12 | AE13: 12 | AF13: 12 | AG13: 12 | AH13: 12 | AJ13: =SUM(E13:AI13) -> 356 | AK13: =VLOOKUP(C13,[2]T09.2026!$C$12:$E$37,3,0) -> KV05390 | AL13: MO | AM13: CO | AP13: =COUNT(E13:AI13)-COUNTIF(E13:AI13,0) -> 28 | AQ13: =AJ13-AS13-AT13 -> 336 | AR13: =IF(AP13=30,2,IF(AP13=29,1,0)) -> 0 | AT13: =(SUMIFS(E13:AI13,E13:AI13,">12")-(COUNTIF(E13:AI13,">12")*12)) -> 20 | AU13: =E13+F13 -> 24
B14: 2 | C14: NGUYỄN THỊ YẾN NHI | D14: KV12514 | E14: 12 | F14: 12 | G14: 12 | H14: 6 | I14: 12 | J14: OFF | K14: 6 | L14: 5 | M14: 6 | N14: 12 | O14: 12 | P14: 12 | Q14: OFF | R14: 7 | S14: 6 | T14: 6 | U14: 12 | V14: 6 | W14: 12 | X14: OFF | Y14: 6 | Z14: 5 | AA14: 6 | AB14: 12 | AC14: 6 | AD14: 12 | AE14: OFF | AF14: 6 | AG14: 5 | AH14: 2 | AJ14: =SUM(E14:AI14) -> 216 | AK14: =VLOOKUP(C14,[2]T09.2026!$C$12:$E$37,3,0) -> KV12514 | AL14: Nhân Viên | AM14: CỔNG KIỂM SOÁT | AN14: 200000 | AP14: =COUNT(E14:AI14)-COUNTIF(E14:AI14,0) -> 26 | AQ14: =AJ14-AS14-AT14 -> 216 | AR14: =IF(AP14=30,2,IF(AP14=29,1,0)) -> 0 | AT14: =(SUMIFS(E14:AI14,E14:AI14,">12")-(COUNTIF(E14:AI14,">12")*12)) -> 0 | AU14: =E14+F14 -> 24
B15: 5 | C15: NGUYỄN NGỌC THANH PHƯƠNG | D15: KV12411 | E15: 12 | F15: 12 | G15: 12 | H15: 12 | I15: 12 | J15: 12 | K15: 12 | L15: 12 | M15: 12 | N15: 12 | O15: 12 | P15: 12 | Q15: 12 | R15: OFF | S15: 12 | T15: 12 | U15: 12 | V15: 12 | W15: 12 | X15: 12 | Y15: 12 | Z15: 12 | AA15: 16 | AB15: 16 | AC15: 12 | AD15: 12 | AE15: 12 | AF15: 12 | AG15: 12 | AH15: 16 | AJ15: =SUM(E15:AI15) -> 360 | AK15: =VLOOKUP(C15,[2]T09.2026!$C$12:$E$37,3,0) -> KV12411 | AL15: Nhân Viên | AM15: CỔNG KIỂM SOÁT | AN15: 200000 | AP15: =COUNT(E15:AI15)-COUNTIF(E15:AI15,0) -> 29 | AQ15: =AJ15-AS15-AT15 -> 336 | AR15: =IF(AP15=30,2,IF(AP15=29,1,0)) -> 1 | AS15: 12 | AT15: =(SUMIFS(E15:AI15,E15:AI15,">12")-(COUNTIF(E15:AI15,">12")*12)) -> 12 | AU15: =E15+F15 -> 24
B16: 6 | C16: TRẦN ANH VIỆT | D16: KV10199 | E16: 12 | F16: 12 | G16: 12 | H16: 12 | I16: 12 | J16: 12 | K16: 12 | L16: 12 | M16: 12 | N16: 12 | O16: 12 | P16: 12 | Q16: 12 | R16: 12 | S16: 12 | T16: 12 | U16: 12 | V16: 12 | W16: 12 | X16: 12 | Y16: 12 | Z16: 12 | AA16: 12 | AB16: 12 | AC16: 12 | AD16: 12 | AE16: 12 | AF16: 12 | AG16: 12 | AH16: 12 | AJ16: =SUM(E16:AI16) -> 360 | AK16: =VLOOKUP(C16,[2]T09.2026!$C$12:$E$37,3,0) -> KV10199 | AL16: Nhân Viên | AM16: CỔNG KIỂM SOÁT | AN16: 200000 | AP16: =COUNT(E16:AI16)-COUNTIF(E16:AI16,0) -> 30 | AQ16: =AJ16-AS16-AT16 -> 336 | AR16: =IF(AP16=30,2,IF(AP16=29,1,0)) -> 2 | AS16: 24 | AT16: =(SUMIFS(E16:AI16,E16:AI16,">12")-(COUNTIF(E16:AI16,">12")*12)) -> 0 | AU16: =E16+F16 -> 24
B17: 5 | C17: ĐINH VĂN GIÚP | D17: KV00389 | E17: 12 | F17: 12 | G17: 12 | H17: 12 | I17: 12 | J17: 12 | K17: 12 | L17: 12 | M17: 12 | N17: 12 | O17: 12 | P17: 12 | Q17: 12 | R17: 12 | S17: 12 | T17: 12 | U17: 12 | V17: 12 | W17: 12 | X17: 12 | Y17: 12 | Z17: 14 | AA17: 12 | AB17: 12 | AC17: 12 | AD17: 12 | AE17: 12 | AF17: OFF | AG17: OFF | AH17: OFF | AJ17: =SUM(E17:AI17) -> 326 | AK17: =VLOOKUP(C17,[2]T09.2026!$C$12:$E$37,3,0) -> KV00389 | AL17: Nhân Viên | AM17: CỔNG KIỂM SOÁT | AN17: 200000 | AP17: =COUNT(E17:AI17)-COUNTIF(E17:AI17,0) -> 27 | AQ17: =AJ17-AS17-AT17 -> 324 | AR17: =IF(AP17=30,2,IF(AP17=29,1,0)) -> 0 | AT17: =(SUMIFS(E17:AI17,E17:AI17,">12")-(COUNTIF(E17:AI17,">12")*12)) -> 2 | AU17: =E17+F17 -> 24
B18: 6 | C18: NGUYỄN VĂN TIẾP | D18: KV02134 | E18: 16 | F18: 16 | G18: 16 | H18: 13 | I18: 13 | J18: 13 | K18: 16 | L18: 16 | M18: 16 | N18: 13 | O18: 13 | P18: OFF | Q18: 16 | R18: 16 | S18: 16 | T18: 16 | U18: 16 | V18: 12 | W18: OFF | X18: 13 | Y18: 16 | Z18: 16 | AA18: 16 | AB18: 16 | AC18: 16 | AD18: 16 | AE18: 13 | AF18: 16 | AG18: 16 | AH18: 16 | AJ18: =SUM(E18:AI18) -> 423 | AK18: =VLOOKUP(C18,[2]T09.2026!$C$12:$E$37,3,0) -> KV02134 | AL18: Nhân Viên | AM18: VỈA HÈ | AN18: 100000 | AP18: =COUNT(E18:AI18)-COUNTIF(E18:AI18,0) -> 28 | AQ18: =AJ18-AS18-AT18 -> 336 | AR18: =IF(AP18=30,2,IF(AP18=29,1,0)) -> 0 | AT18: =(SUMIFS(E18:AI18,E18:AI18,">12")-(COUNTIF(E18:AI18,">12")*12)) -> 87 | AU18: =E18+F18 -> 32
B19: 7 | C19: VÕ PHI HỔ | D19: KV10424 | E19: 12 | F19: 12 | G19: 12 | H19: 16 | I19: 16 | J19: 16 | K19: 12 | L19: 12 | M19: 12 | N19: 16 | O19: 16 | P19: 16 | Q19: 16 | R19: 16 | S19: 12 | T19: 12 | U19: 12 | V19: 16 | W19: 16 | X19: 16 | Y19: 12 | Z19: 12 | AA19: 12 | AB19: 12 | AC19: 12 | AD19: 12 | AE19: 16 | AF19: 12 | AG19: 16 | AH19: 12 | AJ19: =SUM(E19:AI19) -> 412 | AK19: =VLOOKUP(C19,[2]T09.2026!$C$12:$E$37,3,0) -> KV10424 | AL19: Nhân Viên | AM19: VỈA HÈ | AN19: 100000 | AP19: =COUNT(E19:AI19)-COUNTIF(E19:AI19,0) -> 30 | AQ19: =AJ19-AS19-AT19 -> 336 | AR19: =IF(AP19=30,2,IF(AP19=29,1,0)) -> 2 | AS19: 24 | AT19: =(SUMIFS(E19:AI19,E19:AI19,">12")-(COUNTIF(E19:AI19,">12")*12)) -> 52 | AU19: =E19+F19 -> 24
B20: 8 | C20: ĐÀO VĂN NÓI | D20: KV00246 | E20: 12 | F20: 12 | G20: 12 | H20: 12 | I20: 12 | J20: 12 | K20: 12 | L20: 12 | M20: 12 | N20: 12 | O20: 12 | P20: 12 | Q20: 12 | R20: 12 | S20: 12 | T20: 12 | U20: 12 | V20: 12 | W20: 12 | X20: 12 | Y20: 12 | Z20: 12 | AA20: 12 | AB20: OFF | AC20: OFF | AD20: OFF | AE20: OFF | AF20: OFF | AG20: OFF | AH20: OFF | AJ20: =SUM(E20:AI20) -> 276 | AK20: =VLOOKUP(C20,[2]T09.2026!$C$12:$E$37,3,0) -> KV00246 | AL20: Nhân Viên | AM20: HẦM | AP20: =COUNT(E20:AI20)-COUNTIF(E20:AI20,0) -> 23 | AQ20: =AJ20-AS20-AT20 -> 276 | AR20: =IF(AP20=30,2,IF(AP20=29,1,0)) -> 0 | AT20: =(SUMIFS(E20:AI20,E20:AI20,">12")-(COUNTIF(E20:AI20,">12")*12)) -> 0 | AU20: =E20+F20 -> 24
B21: 9 | C21: NGUYỄN VĂN NÚI | D21: KV10065 | E21: 12 | F21: 12 | G21: 12 | H21: 12 | I21: 12 | J21: 12 | K21: 12 | L21: 12 | M21: 12 | N21: 12 | O21: 12 | P21: 12 | Q21: 12 | R21: 12 | S21: OFF | T21: 12 | U21: 12 | V21: 12 | W21: 12 | X21: 12 | Y21: 12 | Z21: 12 | AA21: 12 | AB21: 12 | AC21: 12 | AD21: 12 | AE21: 12 | AF21: 12 | AG21: 12 | AH21: 12 | AJ21: =SUM(E21:AI21) -> 348 | AK21: =VLOOKUP(C21,[2]T09.2026!$C$12:$E$37,3,0) -> KV10065 | AL21: Nhân Viên | AM21: HẦM | AP21: =COUNT(E21:AI21)-COUNTIF(E21:AI21,0) -> 29 | AQ21: =AJ21-AS21-AT21 -> 336 | AR21: =IF(AP21=30,2,IF(AP21=29,1,0)) -> 1 | AS21: 12 | AT21: =(SUMIFS(E21:AI21,E21:AI21,">12")-(COUNTIF(E21:AI21,">12")*12)) -> 0 | AU21: =E21+F21 -> 24
B22: 10 | C22: LÊ VĂN MINH | D22: KV12513 | E22: 12 | F22: 12 | G22: 12 | H22: 12 | I22: 12 | J22: 12 | K22: 12 | L22: 12 | M22: 12 | N22: 16 | O22: 16 | P22: 12 | Q22: 12 | R22: 16 | S22: 12 | T22: 16 | U22: 12 | V22: 16 | W22: 12 | X22: 16 | Y22: 12 | Z22: 12 | AA22: 12 | AB22: 12 | AC22: 12 | AD22: 12 | AE22: 16 | AF22: 12 | AG22: 12 | AH22: 12 | AJ22: =SUM(E22:AI22) -> 388 | AK22: =VLOOKUP(C22,[2]T09.2026!$C$12:$E$37,3,0) -> KV12513 | AL22: Nhân Viên | AM22: VỈA HÈ | AN22: 100000 | AP22: =COUNT(E22:AI22)-COUNTIF(E22:AI22,0) -> 30 | AQ22: =AJ22-AS22-AT22 -> 336 | AR22: =IF(AP22=30,2,IF(AP22=29,1,0)) -> 2 | AS22: 24 | AT22: =(SUMIFS(E22:AI22,E22:AI22,">12")-(COUNTIF(E22:AI22,">12")*12)) -> 28 | AU22: =E22+F22 -> 24
B23: 11 | C23: NGUYỄN VĂN THƯƠNG | D23: KV13026 | E23: 12 | F23: 16 | G23: 12 | H23: 12 | I23: 12 | J23: 12 | K23: 12 | L23: 12 | M23: 12 | N23: 16 | O23: 12 | P23: 12 | Q23: 12 | R23: 12 | S23: 16 | T23: 13 | U23: 16 | V23: 12 | W23: 12 | X23: 12 | Y23: 16 | Z23: 12 | AA23: 12 | AB23: 12 | AC23: 12 | AD23: 12 | AE23: 12 | AF23: 12 | AG23: 16 | AH23: 12 | AJ23: =SUM(E23:AI23) -> 385 | AK23: =VLOOKUP(C23,[2]T09.2026!$C$12:$E$37,3,0) -> KV13026 | AL23: Nhân Viên | AM23: VỈA HÈ | AN23: 100000 | AP23: =COUNT(E23:AI23)-COUNTIF(E23:AI23,0) -> 30 | AQ23: =AJ23-AS23-AT23 -> 336 | AR23: =IF(AP23=30,2,IF(AP23=29,1,0)) -> 2 | AS23: 24 | AT23: =(SUMIFS(E23:AI23,E23:AI23,">12")-(COUNTIF(E23:AI23,">12")*12)) -> 25 | AU23: =E23+F23 -> 28
B24: A | C24: Ca Ngày | D24: MSNV | AP24: =COUNT(E24:AI24)-COUNTIF(E24:AI24,0) -> 0 | AQ24: =AJ24-AS24-AT24 -> 0 | AR24: =IF(AP24=30,2,IF(AP24=29,1,0)) -> 0 | AT24: =(SUMIFS(E24:AI24,E24:AI24,">12")-(COUNTIF(E24:AI24,">12")*12)) -> 0 | AU24: =E24+F24 -> 0
B25: 1 | C25: LƯU VĂN HẢI EM | D25: KV03429 | E25: 13 | F25: 13 | G25: 13 | H25: 13 | I25: 12 | J25: 12 | K25: 13 | L25: 15 | M25: 13 | N25: 15 | O25: 13 | P25: 12 | Q25: 12 | R25: 13 | S25: 13 | T25: 13 | U25: 13 | V25: 13 | W25: 12 | X25: 12 | Y25: 13 | Z25: 13 | AA25: 13 | AB25: 17 | AC25: 13 | AD25: 12 | AE25: 15 | AF25: 13 | AG25: 13 | AH25: 13 | AJ25: =SUM(E25:AI25) -> 393 | AK25: =VLOOKUP(C25,[2]T09.2026!$C$12:$E$37,3,0) -> KV03429 | AL25: MO | AM25: Ca phó | AP25: =COUNT(E25:AI25)-COUNTIF(E25:AI25,0) -> 30 | AQ25: =AJ25-AS25-AT25 -> 336 | AR25: =IF(AP25=30,2,IF(AP25=29,1,0)) -> 2 | AS25: 24 | AT25: =(SUMIFS(E25:AI25,E25:AI25,">12")-(COUNTIF(E25:AI25,">12")*12)) -> 33 | AU25: =E25+F25 -> 26 | AW25: 400000
B26: 2 | C26: ĐINH THỊ KIỀU NƯƠNG | D26: KV00896 | E26: 12 | F26: 12 | G26: 12 | H26: 17 | I26: 17 | J26: 17 | K26: 17 | L26: 12 | M26: 17 | N26: 17 | O26: 17 | P26: 17 | Q26: 16 | R26: 17 | S26: 17 | T26: 17 | U26: 17 | V26: 17 | W26: 12 | X26: 12 | Y26: 12 | Z26: 17 | AA26: 17 | AB26: 17 | AC26: 17 | AD26: 17 | AE26: 16 | AF26: 16 | AG26: 12 | AH26: 17 | AJ26: =SUM(E26:AI26) -> 467 | AK26: =VLOOKUP(C26,[2]T09.2026!$C$12:$E$37,3,0) -> KV00896 | AL26: Nhân Viên | AM26: MO | AP26: =COUNT(E26:AI26)-COUNTIF(E26:AI26,0) -> 30 | AQ26: =AJ26-AS26-AT26 -> 336 | AR26: =IF(AP26=30,2,IF(AP26=29,1,0)) -> 2 | AS26: 24 | AT26: =(SUMIFS(E26:AI26,E26:AI26,">12")-(COUNTIF(E26:AI26,">12")*12)) -> 107 | AU26: =E26+F26 -> 24 | AW26: 400000
B27: 3 | C27: TRẦN THỊ KIM PHƯỢNG | D27: KV03543 | E27: 12 | F27: 12 | G27: 12 | H27: 12 | I27: 12 | J27: 12 | K27: 12 | L27: 12 | M27: 12 | N27: 12 | O27: 12 | P27: 12 | Q27: 12 | R27: 12 | S27: 12 | T27: 12 | U27: 12 | V27: 12 | W27: 12 | X27: 12 | Y27: 12 | Z27: 12 | AA27: 12 | AB27: 12 | AC27: 16 | AD27: 12 | AE27: 12 | AF27: 12 | AG27: 12 | AH27: 12 | AJ27: =SUM(E27:AI27) -> 364 | AK27: =VLOOKUP(C27,[2]T09.2026!$C$12:$E$37,3,0) -> KV03543 | AL27: Nhân Viên | AM27: CỔNG KIỂM SOÁT | AN27: 200000 | AP27: =COUNT(E27:AI27)-COUNTIF(E27:AI27,0) -> 30 | AQ27: =AJ27-AS27-AT27 -> 336 | AR27: =IF(AP27=30,2,IF(AP27=29,1,0)) -> 2 | AS27: 24 | AT27: =(SUMIFS(E27:AI27,E27:AI27,">12")-(COUNTIF(E27:AI27,">12")*12)) -> 4 | AU27: =E27+F27 -> 24 | AW27: 400000
B28: 4 | C28: TRƯƠNG THỊ NO | D28: KV02758 | E28: 12 | F28: 12 | G28: 16 | H28: 13 | I28: 16 | J28: 16 | K28: 17 | L28: 16 | M28: 16 | N28: 16 | O28: 14 | P28: 15 | Q28: 14 | R28: 17 | S28: 16 | T28: 17 | U28: 17 | V28: 16 | W28: 16 | X28: 16 | Y28: 16 | Z28: 16 | AA28: 16 | AB28: 16 | AC28: 16 | AD28: 16 | AE28: 16 | AF28: 17 | AG28: 17 | AH28: 16 | AJ28: =SUM(E28:AI28) -> 470 | AK28: =VLOOKUP(C28,[2]T09.2026!$C$12:$E$37,3,0) -> KV02758 | AL28: Nhân Viên | AM28: CỔNG KIỂM SOÁT | AN28: 200000 | AP28: =COUNT(E28:AI28)-COUNTIF(E28:AI28,0) -> 30 | AQ28: =AJ28-AS28-AT28 -> 336 | AR28: =IF(AP28=30,2,IF(AP28=29,1,0)) -> 2 | AS28: 24 | AT28: =(SUMIFS(E28:AI28,E28:AI28,">12")-(COUNTIF(E28:AI28,">12")*12)) -> 110 | AU28: =E28+F28 -> 24 | AW28: 400000
B29: 5 | C29: HUỲNH NGỌC MINH TRÂM | D29: KV13253 | E29: 15 | F29: 15 | G29: 15 | H29: 12 | I29: 12 | J29: 12 | K29: OFF | L29: 12 | M29: OFF | N29: OFF | O29: 15 | P29: 12 | Q29: 12 | R29: OFF | S29: 12 | T29: 11 | U29: 12 | V29: 12 | W29: 15 | X29: 15 | Y29: 10 | Z29: 12 | AA29: 8 | AB29: OFF | AC29: 15 | AD29: 15 | AE29: 12 | AF29: 12 | AG29: 8 | AH29: 10 | AJ29: =SUM(E29:AI29) -> 311 | AK29: =VLOOKUP(C29,[2]T09.2026!$C$12:$E$37,3,0) -> KV13253 | AL29: Nhân Viên | AM29: CỔNG KIỂM SOÁT | AN29: 200000 | AP29: =COUNT(E29:AI29)-COUNTIF(E29:AI29,0) -> 25 | AQ29: =AJ29-AS29-AT29 -> 287 | AR29: =IF(AP29=30,2,IF(AP29=29,1,0)) -> 0 | AT29: =(SUMIFS(E29:AI29,E29:AI29,">12")-(COUNTIF(E29:AI29,">12")*12)) -> 24 | AU29: =E29+F29 -> 30 | AW29: 400000
B30: 6 | C30: HUỲNH THANH NGA | D30: KV07126 | E30: 16 | F30: 16 | G30: 16 | H30: 17 | I30: 12 | J30: 18 | K30: 17 | L30: 18 | M30: 18 | N30: 17 | O30: 18 | P30: 12 | Q30: 18 | R30: 18 | S30: 18 | T30: 18 | U30: 18 | V30: 18 | W30: 12 | X30: 16 | Y30: 12 | Z30: 17 | AA30: 18 | AB30: 18 | AC30: 17 | AD30: 17 | AE30: 17 | AF30: 18 | AG30: 19 | AH30: 19 | AJ30: =SUM(E30:AI30) -> 503 | AK30: =VLOOKUP(C30,[2]T09.2026!$C$12:$E$37,3,0) -> KV07126 | AL30: Nhân Viên | AM30: CỔNG KIỂM SOÁT | AN30: 200000 | AP30: =COUNT(E30:AI30)-COUNTIF(E30:AI30,0) -> 30 | AQ30: =AJ30-AS30-AT30 -> 336 | AR30: =IF(AP30=30,2,IF(AP30=29,1,0)) -> 2 | AS30: 24 | AT30: =(SUMIFS(E30:AI30,E30:AI30,">12")-(COUNTIF(E30:AI30,">12")*12)) -> 143 | AU30: =E30+F30 -> 32 | AW30: 400000
B31: 7 | C31: NGUYỄN VĂN CẢNH | D31: KV09760 | E31: 12 | F31: 12 | G31: 12 | H31: 12 | I31: 12 | J31: 12 | K31: 12 | L31: 12 | M31: 12 | N31: 12 | O31: 12 | P31: 12 | Q31: 12 | R31: 12 | S31: 12 | T31: 12 | U31: 12 | V31: 12 | W31: 12 | X31: 12 | Y31: 12 | Z31: 12 | AA31: 12 | AB31: 12 | AC31: 12 | AD31: 12 | AE31: 12 | AF31: 15 | AG31: 15 | AH31: 12 | AJ31: =SUM(E31:AI31) -> 366 | AK31: =VLOOKUP(C31,[2]T09.2026!$C$12:$E$37,3,0) -> KV09760 | AL31: Nhân Viên | AM31: VỈA HÈ | AN31: 100000 | AP31: =COUNT(E31:AI31)-COUNTIF(E31:AI31,0) -> 30 | AQ31: =AJ31-AS31-AT31 -> 336 | AR31: =IF(AP31=30,2,IF(AP31=29,1,0)) -> 2 | AS31: 24 | AT31: =(SUMIFS(E31:AI31,E31:AI31,">12")-(COUNTIF(E31:AI31,">12")*12)) -> 6 | AU31: =E31+F31 -> 24 | AW31: 400000
B32: 8 | C32: VÕ TRỌNG PHÚC | D32: KV11844 | E32: 12 | F32: 12 | G32: 12 | H32: 12 | I32: 12 | J32: 12 | K32: 12 | L32: 12 | M32: 12 | N32: 12 | O32: 12 | P32: 12 | Q32: 12 | R32: 12 | S32: 12 | T32: 12 | U32: 12 | V32: 12 | W32: 12 | X32: 12 | Y32: 12 | Z32: 12 | AA32: 12 | AB32: 12 | AC32: 12 | AD32: 12 | AE32: 12 | AF32: 12 | AG32: 12 | AH32: 12 | AJ32: =SUM(E32:AI32) -> 360 | AK32: =VLOOKUP(C32,[2]T09.2026!$C$12:$E$37,3,0) -> KV11844 | AL32: Nhân Viên | AM32: VỈA HÈ | AN32: 100000 | AP32: =COUNT(E32:AI32)-COUNTIF(E32:AI32,0) -> 30 | AQ32: =AJ32-AS32-AT32 -> 336 | AR32: =IF(AP32=30,2,IF(AP32=29,1,0)) -> 2 | AS32: 24 | AT32: =(SUMIFS(E32:AI32,E32:AI32,">12")-(COUNTIF(E32:AI32,">12")*12)) -> 0 | AU32: =E32+F32 -> 24 | AW32: 400000
B33: 9 | C33: NGUYỄN QUỲNH NHƯ | D33: KV07238 | E33: 8 | F33: 10 | G33: 8 | H33: 8 | I33: 8 | J33: 8 | K33: 11 | L33: 8 | M33: 11 | N33: 11 | O33: 11 | P33: 8 | Q33: 8 | R33: 12 | S33: 8 | T33: 11 | U33: 8 | V33: 8 | W33: 8 | X33: 8 | Y33: 11 | Z33: 8 | AA33: 8 | AB33: 8 | AC33: 12 | AD33: 12 | AE33: 12 | AF33: 12 | AG33: 12 | AH33: 12 | AJ33: =SUM(E33:AI33) -> 288 | AK33: =VLOOKUP(C33,[2]T09.2026!$C$12:$E$37,3,0) -> KV07238 | AL33: Nhân Viên | AM33: VỈA HÈ | AN33: 100000 | AP33: =COUNT(E33:AI33)-COUNTIF(E33:AI33,0) -> 30 | AQ33: =AJ33-AS33-AT33 -> 264 | AR33: =IF(AP33=30,2,IF(AP33=29,1,0)) -> 2 | AS33: 24 | AT33: =(SUMIFS(E33:AI33,E33:AI33,">12")-(COUNTIF(E33:AI33,">12")*12)) -> 0 | AU33: =E33+F33 -> 18
AP34: =COUNT(E34:AI34)-COUNTIF(E34:AI34,0) -> 0 | AQ34: =AJ34-AS34-AT34 -> 0 | AR34: =IF(AP34=30,2,IF(AP34=29,1,0)) -> 0 | AT34: =(SUMIFS(E34:AI34,E34:AI34,">12")-(COUNTIF(E34:AI34,">12")*12)) -> 0 | AU34: =E34+F34 -> 0
C35: Đến hỗ trợ Ca Ngày | AP35: =COUNT(E35:AI35)-COUNTIF(E35:AI35,0) -> 0 | AQ35: =AJ35-AS35-AT35 -> 0 | AR35: =IF(AP35=30,2,IF(AP35=29,1,0)) -> 0 | AT35: =(SUMIFS(E35:AI35,E35:AI35,">12")-(COUNTIF(E35:AI35,">12")*12)) -> 0 | AU35: =E35+F35 -> 0
B36: 1 | C36: NGUYỄN VĂN NHÂN | D36: KV13007 | AG36: 12 | AJ36: =SUM(E36:AI36) -> 12 | AK36: =VLOOKUP(C36,[2]T09.2026!$C$12:$E$37,3,0) -> KV13007 | AP36: =COUNT(E36:AI36)-COUNTIF(E36:AI36,0) -> 1 | AQ36: =AJ36-AS36-AT36 -> 12 | AR36: =IF(AP36=30,2,IF(AP36=29,1,0)) -> 0 | AT36: =(SUMIFS(E36:AI36,E36:AI36,">12")-(COUNTIF(E36:AI36,">12")*12)) -> 0 | AU36: =E36+F36 -> 0
B37: E | C37: Đến hỗ trợ Ca Đêm | AP37: =COUNT(E37:AI37)-COUNTIF(E37:AI37,0) -> 0 | AQ37: =AJ37-AS37-AT37 -> 0 | AR37: =IF(AP37=30,2,IF(AP37=29,1,0)) -> 0 | AT37: =(SUMIFS(E37:AI37,E37:AI37,">12")-(COUNTIF(E37:AI37,">12")*12)) -> 0 | AU37: =E37+F37 -> 0
B38: 1 | C38: HUỲNH THANH TÂM | D38: KV12839 | E38: 16 | F38: OFF | G38: 12 | H38: 12 | I38: 12 | J38: 12 | K38: 12 | L38: 12 | M38: 12 | N38: 12 | O38: OFF | P38: 12 | Q38: 18 | R38: OFF | S38: 12 | T38: 12 | U38: 12 | V38: 12 | W38: 12 | X38: 16 | Y38: OFF | Z38: 12 | AA38: 5 | AB38: 5 | AC38: 12 | AD38: 12 | AE38: 17 | AF38: OFF | AG38: 5 | AH38: OFF | AI38: =SUM(T38:AH38) -> 132 | AP38: =COUNT(E38:AI38)-COUNTIF(E38:AI38,0) -> 25 | AQ38: =AJ38-AS38-AT38 -> -139 | AR38: =IF(AP38=30,2,IF(AP38=29,1,0)) -> 0 | AT38: =(SUMIFS(E38:AI38,E38:AI38,">12")-(COUNTIF(E38:AI38,">12")*12)) -> 139
B39: 2 | C39: ĐẶNG LƯ PHƯƠNG HIẾU | D39: KV13261 | AH39: 12 | AJ39: =SUM(E39:AI39) -> 12 | AK39: =VLOOKUP(C39,[2]T09.2026!$C$12:$E$37,3,0) -> KV13261 | AP39: =COUNT(E39:AI39)-COUNTIF(E39:AI39,0) -> 1 | AQ39: =AJ39-AS39-AT39 -> 12 | AR39: =IF(AP39=30,2,IF(AP39=29,1,0)) -> 0 | AT39: =(SUMIFS(E39:AI39,E39:AI39,">12")-(COUNTIF(E39:AI39,">12")*12)) -> 0 | AU39: =E39+F39 -> 0
B43: F | C43: Đi hỗ trợ | AP43: =COUNT(E43:AI43)-COUNTIF(E43:AI43,0) -> 0 | AQ43: =AJ43-AS43-AT43 -> 0 | AR43: =IF(AP43=30,2,IF(AP43=29,1,0)) -> 0 | AT43: =(SUMIFS(E43:AI43,E43:AI43,">12")-(COUNTIF(E43:AI43,">12")*12)) -> 0 | AU43: =E43+F43 -> 0
...

Sheet DCH
B1: BẢNG CHẤM CÔNG NHÂN VIÊN THÁNG 10/2019 | AM1: - Những cột có dấu (*) là bắt buộc người chấm công phải nhập dữ liệu (nếu có)
B2: ( Từ Ngày : 01/10/2019 Đến : 31/10/2019 )
C3: Bãi xe : DEUTSCHES HAUS | AM3: Phần nhập của Quản lý Bãi xe | AQ3: Phần nhập của Phòng HCNS
AM4: (*) | AN4: (*) | AO4: (*) | AP4: (*)
D5: 1 | E5: 2 | F5: 3 | G5: 4 | H5: 5 | I5: 6 | J5: 7 | K5: 8 | L5: 9 | M5: 10 | N5: 11 | O5: 12 | P5: 13 | Q5: 14 | R5: 15 | S5: 16 | T5: 17 | U5: 18 | V5: 19 | W5: 20 | X5: 21 | Y5: 22 | Z5: 23 | AA5: 24 | AB5: 25 | AC5: 26 | AD5: 27 | AE5: 28 | AF5: 29 | AG5: 30 | AH5: 31 | AI5: 32 | AJ5: 33 | AK5: 34 | AL5: 35 | AM5: 36 | AN5: 37 | AO5: 38 | AP5: 39 | AQ5: 40 | AR5: 41 | AS5: 42 | AT5: 43 | AU5: 44 | AV5: 45 | AW5: 46 | AX5: 47 | AY5: 48
B6: Phần in ra cho Nhân viên ký xác nhận
B7: STT | C7: HỌ VÀ TÊN | D7: Thứ | F7: =TEXT(F8,"ddd") -> T3 | G7: =TEXT(G8,"ddd") -> T4 | H7: =TEXT(H8,"ddd") -> T5 | I7: =TEXT(I8,"ddd") -> T6 | J7: =TEXT(J8,"ddd") -> T7 | K7: =TEXT(K8,"ddd") -> CN | L7: =TEXT(L8,"ddd") -> T2 | M7: =TEXT(M8,"ddd") -> T3 | ... AJ7: =TEXT(AJ8,"ddd") | AL7: NV Ký Xác nhận | AM7: Thông tin Tham chiếu | AQ7: Giờ công (h) | AX7: Đánh giá
D8: Ngày | F8: =DATE(SGP!D7,SGP!D6,1) -> 46266 | G8: =IFERROR(IF(F8+1<=EOMONTH(F8,0),F8+1,""),"") -> 46267 | H8: =IFERROR(IF(G8+1<=EOMONTH(G8,0),G8+1,""),"") -> 46268 | I8: =IFERROR(IF(H8+1<=EOMONTH(H8,0),H8+1,""),"") -> 46269 | J8: =IFERROR(IF(I8+1<=EOMONTH(I8,0),I8+1,""),"") -> 46270 | K8: =IFERROR(IF(J8+1<=EOMONTH(J8,0),J8+1,""),"") -> 46271 | L8: =IFERROR(IF(K8+1<=EOMONTH(K8,0),K8+1,""),"") -> 46272 | M8: =IFERROR(IF(L8+1<=EOMONTH(L8,0),L8+1,""),"") -> 46273 | N8: =IFERROR(IF(M8+1<=EOMONTH(M8,0),M8+1,""),"") -> 46274 | ... AJ8: =IFERROR(IF(AI8+1<=EOMONTH(AI8,0),AI8+1,""),"") | AK8: Tổng giờ Công | AM8: Đối tượng / Chức vụ | AN8: Ghi chú (ghi chú phụ cấp) | AO8: Bãi xe (chỉ ghi khi có NV đến hỗ trợ) | AP8: Ca làm việc | AQ8: Tổng số ngày Làm việc trong tháng | AR8: Giờ công thường 1.0 | AS8: Số ngày tăng ca ngày nghỉ | AT8: Tăng ca ngày 1.3 | AU8: Tăng ca giờ 1.5 | AV8: Tăng ca Lễ 2.0 | AW8: Tăng ca tết 3.0 | AX8: Bãi xe Đánh giá | AY8: P. Nhân sự đánh giá
B9: A | C9: Ca Ngày | D9: MSNV | E9: Ngày vào làm | AM9: 5 CỔNG | AW9: 0 | AX9: 0 | AY9: 0
B10: 1 | C10: LÂM ĐỖ LÊ DUY | D10: KV4623 | E10: ĐỘI TRƯỞNG | F10: OFF | G10: OFF | H10: 12 | I10: 12 | J10: 12 | K10: OFF | L10: 12 | M10: 12 | N10: 12 | O10: 12 | P10: 12 | Q10: 12 | R10: OFF | S10: 12 | T10: 12 | U10: 12 | V10: 12 | W10: 12 | X10: 12 | Y10: OFF | Z10: 12 | AA10: 12 | AB10: 12 | AC10: 12 | AD10: 12 | AE10: 12 | AF10: OFF | AG10: 12 | AH10: 12 | AI10: 12 | AM10: Đội Trưởng
B11: 2 | C11: NGUYỄN HỮU THẬT | D11: KV04146 | E11: 26/08/2026 | F11: 12 | G11: 16 | H11: 12 | I11: 12 | J11: 12 | K11: 14 | L11: 13 | M11: 12 | N11: 14 | O11: 12 | P11: 9 | Q11: 16 | R11: 14.5 | S11: 12 | T11: 12 | U11: 16 | V11: 16 | W11: 12 | X11: 12 | Y11: 12 | Z11: 12 | AA11: 12 | AB11: 12 | AC11: 12 | AD11: 12 | AE11: 16 | AF11: 12 | AG11: 12 | AH11: 13 | AI11: 12 | AK11: =SUM(F11:AJ11) -> 385.5 | AL11: =VLOOKUP(C11,[2]T09.2026!$C$41:$E$65,3,0) -> KV04146 | AM11: MO | AQ11: =COUNT(F11:AJ11)-COUNTIF(F11:AJ11,0) -> 30 | AR11: =AK11-AT11-AU11 -> 333 | AS11: =IF(AQ11=30,2,IF(AQ11=29,1,0)) -> 2 | AT11: 24 | AU11: =(SUMIFS(F11:AJ11,F11:AJ11,">12")-(COUNTIF(F11:AJ11,">12")*12)) -> 28.5 | AV11: =F11+G11 -> 28
B12: 3 | C12: LÊ CÔNG QUÂN | D12: KV08665 | E12: 44602 | F12: 10 | G12: 10 | H12: 10 | I12: 10 | J12: OFF | K12: 10 | L12: 10 | M12: 10 | N12: 10 | O12: 10 | P12: 10 | Q12: 10 | R12: 10 | S12: 10 | T12: 10 | U12: 10 | V12: 10 | W12: 10 | X12: OFF | Y12: 10 | Z12: 10 | AA12: 10 | AB12: 10 | AC12: 10 | AD12: 10 | AE12: 10 | AF12: 4 | AG12: 10 | AH12: 10 | AI12: 10 | AK12: =SUM(F12:AJ12) -> 274 | AL12: =VLOOKUP(C12,[2]T09.2026!$C$41:$E$65,3,0) -> KV08665 | AM12: Nhân Viên | AN12: Phụ cấp cổng | AO12: 200000 | AQ12: =COUNT(F12:AJ12)-COUNTIF(F12:AJ12,0) -> 28 | AR12: =AK12-AT12-AU12 -> 274 | AS12: =IF(AQ12=30,2,IF(AQ12=29,1,0)) -> 0 | AU12: =(SUMIFS(F12:AJ12,F12:AJ12,">12")-(COUNTIF(F12:AJ12,">12")*12)) -> 0 | AV12: =F12+G12 -> 20
B13: 4 | C13: TRỊNH HẢI ANH | D13: KV12085 | E13: 45775 | F13: OFF | G13: 12 | H13: 12 | I13: 12 | J13: 12 | K13: 12 | L13: 12 | M13: 12 | N13: 12 | O13: 12 | P13: 12 | Q13: 12 | R13: 12 | S13: 12 | T13: 12 | U13: 12 | V13: OFF | W13: OFF | X13: 12 | Y13: 12 | Z13: 12 | AA13: 12 | AB13: 12 | AC13: 12 | AD13: 12 | AE13: 10.5 | AF13: 12 | AG13: 12 | AH13: 12 | AI13: 12 | AK13: =SUM(F13:AJ13) -> 322.5 | AL13: =VLOOKUP(C13,[2]T09.2026!$C$41:$E$65,3,0) -> KV12085 | AM13: Nhân Viên | AQ13: =COUNT(F13:AJ13)-COUNTIF(F13:AJ13,0) -> 27 | AR13: =AK13-AT13-AU13 -> 322.5 | AS13: =IF(AQ13=30,2,IF(AQ13=29,1,0)) -> 0 | AU13: =(SUMIFS(F13:AJ13,F13:AJ13,">12")-(COUNTIF(F13:AJ13,">12")*12)) -> 0 | AV13: 12 | AY13: A
B14: 5 | C14: GỊP DUY BÌNH | D14: KV08846 | E14: 45876 | F14: 12 | G14: 12 | H14: 12 | I14: 12 | J14: 12 | K14: 12 | L14: 12 | M14: 12 | N14: 12 | O14: 12 | P14: 12 | Q14: 12 | R14: 12 | S14: 12.5 | T14: 12 | U14: 12 | V14: 12 | W14: 12 | X14: 12 | Y14: 12 | Z14: 12 | AA14: 12 | AB14: 12 | AC14: 12 | AD14: 12 | AE14: 12 | AF14: 12 | AG14: 12 | AH14: 12 | AI14: 12 | AK14: =SUM(F14:AJ14) -> 360.5 | AL14: =VLOOKUP(C14,[2]T09.2026!$C$41:$E$65,3,0) -> KV08846 | AM14: Nhân Viên | AQ14: =COUNT(F14:AJ14)-COUNTIF(F14:AJ14,0) -> 30 | AR14: =AK14-AT14-AU14 -> 336 | AS14: =IF(AQ14=30,2,IF(AQ14=29,1,0)) -> 2 | AT14: 24 | AU14: =(SUMIFS(F14:AJ14,F14:AJ14,">12")-(COUNTIF(F14:AJ14,">12")*12)) -> 0.5 | AV14: =F14+G14 -> 24 | AY14: A
B15: 6 | C15: PHẠM HOÀNG HỒNG YẾN | D15: KV12415 | E15: 45890 | F15: 12 | G15: 12 | H15: 12 | I15: 12 | J15: 12 | K15: 12 | L15: 12 | M15: 12 | N15: 12 | O15: 12 | P15: 12 | Q15: 12 | R15: 12 | S15: 12.5 | T15: 12 | U15: 12 | V15: 12 | W15: 12 | X15: 12 | Y15: OFF | Z15: 12 | AA15: 12 | AB15: 12 | AC15: 12 | AD15: 12 | AE15: 12 | AF15: 12 | AG15: 12 | AH15: 12 | AI15: OFF | AK15: =SUM(F15:AJ15) -> 336.5 | AL15: =VLOOKUP(C15,[2]T09.2026!$C$41:$E$65,3,0) -> KV12415 | AM15: Nhân Viên | AN15: Phụ cấp cổng | AO15: 200000 | AQ15: =COUNT(F15:AJ15)-COUNTIF(F15:AJ15,0) -> 28 | AR15: =AK15-AT15-AU15 -> 336 | AS15: =IF(AQ15=30,2,IF(AQ15=29,1,0)) -> 0 | AU15: =(SUMIFS(F15:AJ15,F15:AJ15,">12")-(COUNTIF(F15:AJ15,">12")*12)) -> 0.5 | AV15: =F15+G15 -> 24 | AY15: A
B16: 7 | C16: TRẦN ANH HUY | D16: KV12611 | E16: 16/11/2025 | F16: 12 | G16: 12 | H16: 12 | I16: 12 | J16: 12 | K16: 12 | L16: 12 | M16: 12 | N16: 12 | O16: 12 | P16: 12 | Q16: OFF | R16: OFF | S16: OFF | T16: 12.5 | U16: 12 | V16: 12 | W16: 12 | X16: 12 | Y16: 12 | Z16: 12 | AA16: 12 | AB16: 12 | AC16: 12 | AD16: 12 | AE16: OFF | AF16: 12 | AG16: 12 | AH16: 12 | AI16: 12 | AK16: =SUM(F16:AJ16) -> 312.5 | AL16: =VLOOKUP(C16,[2]T09.2026!$C$41:$E$65,3,0) -> KV12611 | AM16: Nhân Viên | AQ16: =COUNT(F16:AJ16)-COUNTIF(F16:AJ16,0) -> 26 | AR16: =AK16-AT16-AU16 -> 312 | AS16: =IF(AQ16=30,2,IF(AQ16=29,1,0)) -> 0 | AU16: =(SUMIFS(F16:AJ16,F16:AJ16,">12")-(COUNTIF(F16:AJ16,">12")*12)) -> 0.5 | AV16: =F16+G16 -> 24 | AY16: A
B17: 8 | C17: LÊ VÕ TRỌNG NHÂN | D17: KV12965 | E17: 22/03/2026 | F17: 12 | G17: 12 | H17: 12 | I17: 12 | J17: 12 | K17: 12 | L17: 12 | M17: 12 | N17: 12 | O17: 12 | P17: 12 | Q17: 12 | R17: 12 | S17: 12 | T17: 9 | U17: 12 | V17: 12 | W17: 12 | X17: 12 | Y17: 12 | Z17: 12 | AA17: 12 | AB17: 12 | AC17: 12 | AD17: 12 | AE17: 12 | AF17: 12 | AG17: OFF | AH17: 12 | AI17: 12 | AK17: =SUM(F17:AJ17) -> 345 | AL17: =VLOOKUP(C17,[2]T09.2026!$C$41:$E$65,3,0) -> KV12965 | AM17: Nhân Viên | AN17: Phụ cấp cổng | AO17: 200000 | AQ17: =COUNT(F17:AJ17)-COUNTIF(F17:AJ17,0) -> 29 | AR17: =AK17-AT17-AU17 -> 333 | AS17: =IF(AQ17=30,2,IF(AQ17=29,1,0)) -> 1 | AT17: 12 | AU17: =(SUMIFS(F17:AJ17,F17:AJ17,">12")-(COUNTIF(F17:AJ17,">12")*12)) -> 0 | AV17: =F17+G17 -> 24
B18: 9 | C18: NGUYỄN THỊ MỸ TÚ | D18: KV13217 | E18: 15/06/2026 | F18: 12 | G18: 12 | H18: 12 | I18: 12 | J18: 12 | K18: OFF | L18: 12 | M18: 12 | N18: 12 | O18: 12 | P18: 12 | Q18: OFF | R18: 12 | S18: 12 | T18: OFF | U18: 12 | V18: 12 | W18: 12 | X18: 12 | Y18: 12 | Z18: 12 | AA18: OFF | AB18: 12 | AC18: 12 | AD18: 12 | AE18: 12 | AF18: 12 | AG18: 12 | AH18: 12 | AI18: 12 | AK18: =SUM(F18:AJ18) -> 312 | AL18: =VLOOKUP(C18,[2]T09.2026!$C$41:$E$65,3,0) -> KV13217 | AM18: Nhân Viên | AN18: Phụ cấp cổng | AO18: 200000 | AQ18: =COUNT(F18:AJ18)-COUNTIF(F18:AJ18,0) -> 26 | AR18: =AK18-AT18-AU18 -> 312 | AS18: =IF(AQ18=30,2,IF(AQ18=29,1,0)) -> 0 | AU18: =(SUMIFS(F18:AJ18,F18:AJ18,">12")-(COUNTIF(F18:AJ18,">12")*12)) -> 0 | AV18: =F18+G18 -> 24
B19: 10 | C19: HÀ LỆ KIM | D19: KV13258 | E19: 25/06/2026 | F19: 12 | G19: 12 | H19: 12 | I19: 12 | J19: 12 | K19: OFF | L19: OFF | M19: 12 | N19: 12 | O19: 12 | P19: 12 | Q19: 12 | R19: 12 | S19: 12 | T19: OFF | U19: OFF | V19: 12 | W19: 12 | X19: 12 | Y19: 12 | Z19: 12 | AA19: 12 | AB19: 12 | AC19: 12 | AD19: 12 | AE19: 12 | AF19: 12 | AG19: 12 | AH19: 12 | AI19: 12 | AK19: =SUM(F19:AJ19) -> 312 | AL19: =VLOOKUP(C19,[2]T09.2026!$C$41:$E$65,3,0) -> KV13258 | AM19: Nhân Viên | AN19: Phụ cấp cổng | AO19: 200000 | AQ19: =COUNT(F19:AJ19)-COUNTIF(F19:AJ19,0) -> 26 | AR19: =AK19-AT19-AU19 -> 312 | AS19: =IF(AQ19=30,2,IF(AQ19=29,1,0)) -> 0 | AU19: =(SUMIFS(F19:AJ19,F19:AJ19,">12")-(COUNTIF(F19:AJ19,">12")*12)) -> 0 | AV19: =F19+G19 -> 24
B20: B | C20: Ca Đêm | AQ20: =COUNT(F20:AJ20)-COUNTIF(F20:AJ20,0) -> 0 | AR20: =AK20-AT20-AU20 -> 0 | AS20: =IF(AQ20=30,2,IF(AQ20=29,1,0)) -> 0 | AU20: =(SUMIFS(F20:AJ20,F20:AJ20,">12")-(COUNTIF(F20:AJ20,">12")*12)) -> 0 | AV20: =F20+G20 -> 0
B21: 1 | C21: PHẠM THỊ KIM LIÊN | D21: KV10972 | E21: 45379 | F21: 12 | G21: 14 | H21: 12 | I21: 12 | J21: 12 | K21: 16 | L21: 12 | M21: 12 | N21: 12 | O21: 12 | P21: 14 | Q21: OFF | R21: 12 | S21: 12 | T21: 16 | U21: 12 | V21: 12 | W21: 12 | X21: 12 | Y21: 12 | Z21: 12 | AA21: 16 | AB21: 12 | AC21: 12 | AD21: 12 | AE21: OFF | AF21: 13.5 | AG21: 12 | AH21: 12 | AI21: 13 | AK21: =SUM(F21:AJ21) -> 354.5 | AL21: =VLOOKUP(C21,[2]T09.2026!$C$41:$E$65,3,0) -> KV10972 | AM21: MO | AQ21: =COUNT(F21:AJ21)-COUNTIF(F21:AJ21,0) -> 28 | AR21: =AK21-AT21-AU21 -> 336 | AS21: =IF(AQ21=30,2,IF(AQ21=29,1,0)) -> 0 | AU21: =(SUMIFS(F21:AJ21,F21:AJ21,">12")-(COUNTIF(F21:AJ21,">12")*12)) -> 18.5 | AV21: =F21+G21 -> 26 | AX21: 400000
B22: 2 | C22: ĐÀO MINH HÀ | D22: KV01766 | E22: 45020 | F22: 12 | G22: 12 | H22: 12 | I22: 12 | J22: 12 | K22: 10 | L22: 12 | M22: 12 | N22: 12 | O22: 12 | P22: 12 | Q22: 12 | R22: 9.5 | S22: 12 | T22: 12 | U22: 12 | V22: 12 | W22: 12 | X22: 11 | Y22: 12 | Z22: 12 | AA22: 12 | AB22: 12 | AC22: 12 | AD22: 12 | AE22: OFF | AF22: 12 | AG22: 12 | AH22: 12 | AI22: 12 | AK22: =SUM(F22:AJ22) -> 342.5 | AL22: =VLOOKUP(C22,[2]T09.2026!$C$41:$E$65,3,0) -> KV01766 | AM22: Nhân Viên | AQ22: =COUNT(F22:AJ22)-COUNTIF(F22:AJ22,0) -> 29 | AR22: =AK22-AT22-AU22 -> 330.5 | AS22: =IF(AQ22=30,2,IF(AQ22=29,1,0)) -> 1 | AT22: 12 | AU22: =(SUMIFS(F22:AJ22,F22:AJ22,">12")-(COUNTIF(F22:AJ22,">12")*12)) -> 0 | AV22: =F22+G22 -> 24 | AX22: 400000
B23: 3 | C23: CHU LÂM TRƯỜNG TOÀN | D23: KV09825 | E23: 45710 | F23: 12 | G23: 12 | H23: 12 | I23: 12 | J23: 12 | K23: 12 | L23: 12 | M23: 12 | N23: 12 | O23: 12 | P23: 12 | Q23: 12 | R23: 13 | S23: 11.5 | T23: 12 | U23: 12 | V23: 12 | W23: 12 | X23: 12 | Y23: 12 | Z23: 12 | AA23: 12 | AB23: 12 | AC23: 12 | AD23: 12 | AE23: 12 | AF23: 12 | AG23: 12 | AH23: 11 | AI23: 12 | AK23: =SUM(F23:AJ23) -> 359.5 | AL23: =VLOOKUP(C23,[2]T09.2026!$C$41:$E$65,3,0) -> KV09825 | AM23: Nhân Viên | AN23: Phụ cấp cổng | AO23: 200000 | AQ23: =COUNT(F23:AJ23)-COUNTIF(F23:AJ23,0) -> 30 | AR23: =AK23-AT23-AU23 -> 335.5 | AS23: =IF(AQ23=30,2,IF(AQ23=29,1,0)) -> 2 | AT23: 23 | AU23: =(SUMIFS(F23:AJ23,F23:AJ23,">12")-(COUNTIF(F23:AJ23,">12")*12)) -> 1 | AV23: =F23+G23 -> 24 | AX23: 400000
B24: 4 | C24: NGUYỄN HOÀNG ANH THƯ | D24: KV13327 | E24: 23/7/2026 | F24: 12 | G24: 12 | H24: 12 | I24: 14 | J24: 16 | K24: 12 | L24: 11 | M24: 12 | N24: 12 | O24: 12 | P24: 15 | Q24: 16 | R24: 12 | S24: OFF | T24: OFF | U24: OFF | V24: OFF | W24: 12 | X24: 12 | Y24: 12 | Z24: 12 | AA24: 16 | AB24: 12 | AC24: 12 | AD24: 12 | AE24: 12 | AF24: 16 | AG24: 12 | AH24: 12 | AI24: 12 | AK24: =SUM(F24:AJ24) -> 332 | AL24: =VLOOKUP(C24,[2]T09.2026!$C$41:$E$65,3,0) -> KV13327 | AM24: Nhân Viên | AN24: Phụ cấp cổng | AO24: 200000 | AQ24: =COUNT(F24:AJ24)-COUNTIF(F24:AJ24,0) -> 26 | AR24: =AK24-AT24-AU24 -> 311 | AS24: =IF(AQ24=30,2,IF(AQ24=29,1,0)) -> 0 | AU24: =(SUMIFS(F24:AJ24,F24:AJ24,">12")-(COUNTIF(F24:AJ24,">12")*12)) -> 21 | AV24: =F24+G24 -> 24 | AX24: 400000
B25: 5 | C25: NGUYỄN ĐÌNH HOÀNG HẢI | D25: KV13332 | E25: 25/07/2026 | F25: 12 | G25: 12 | H25: 12 | I25: 12 | J25: 12 | K25: 12.5 | L25: 12 | M25: 12 | N25: 10 | O25: 12 | P25: 12 | Q25: 13 | R25: 12 | S25: 16 | T25: 11 | U25: 16 | V25: 12 | W25: 12 | X25: 13 | Y25: 13 | Z25: 12 | AA25: 16 | AB25: 12 | AC25: 12 | AD25: 12 | AE25: 13.5 | AF25: 13 | AG25: 16 | AH25: 11 | AI25: 12 | AK25: =SUM(F25:AJ25) -> 378 | AL25: =VLOOKUP(C25,[2]T09.2026!$C$41:$E$65,3,0) -> KV13332 | AM25: Nhân Viên | AQ25: =COUNT(F25:AJ25)-COUNTIF(F25:AJ25,0) -> 30 | AR25: =AK25-AT25-AU25 -> 333 | AS25: =IF(AQ25=30,2,IF(AQ25=29,1,0)) -> 2 | AT25: 23 | AU25: =(SUMIFS(F25:AJ25,F25:AJ25,">12")-(COUNTIF(F25:AJ25,">12")*12)) -> 22 | AV25: =F25+G25 -> 24 | AX25: 400000
B26: 6 | C26: PHẠM LÂM MINH TRÍ | D26: KV08922 | E26: 16/08/2026 | F26: 12 | G26: OFF | H26: 12 | I26: 12 | J26: 12 | K26: 12 | L26: 12 | M26: 12 | N26: 12 | O26: 12 | P26: 12 | Q26: 12 | R26: 12 | S26: 12 | T26: 12 | U26: OFF | V26: OFF | W26: 12 | X26: 12 | Y26: 12 | Z26: 12 | AA26: 12 | AB26: 12 | AC26: 12 | AD26: 12 | AE26: 12 | AF26: 12 | AG26: 12 | AH26: 12 | AI26: 12 | AK26: =SUM(F26:AJ26) -> 324 | AL26: =VLOOKUP(C26,[2]T09.2026!$C$41:$E$65,3,0) -> KV08922 | AM26: Nhân Viên | AN26: Phụ cấp cổng | AO26: 200000 | AQ26: =COUNT(F26:AJ26)-COUNTIF(F26:AJ26,0) -> 27 | AR26: =AK26-AT26-AU26 -> 324 | AS26: =IF(AQ26=30,2,IF(AQ26=29,1,0)) -> 0 | AU26: =(SUMIFS(F26:AJ26,F26:AJ26,">12")-(COUNTIF(F26:AJ26,">12")*12)) -> 0 | AV26: 12 | AX26: 400000
B27: 7 | C27: VŨ HOÀNG LONG | D27: KV13406 | E27: 26/08/2026 | F27: 12 | G27: 12 | H27: 12 | I27: 12 | J27: 12 | K27: 12 | L27: 12 | M27: 12 | N27: 12 | O27: 12 | P27: 12 | Q27: 12 | R27: 12 | S27: 12 | T27: 15 | U27: 12 | V27: 12 | W27: 12 | X27: 12 | Y27: 12 | Z27: 12 | AA27: 12 | AB27: 12 | AC27: 12 | AD27: 12 | AE27: 12 | AF27: 12 | AG27: 12 | AH27: 12 | AI27: 12 | AK27: =SUM(F27:AJ27) -> 363 | AL27: =VLOOKUP(C27,[2]T09.2026!$C$41:$E$65,3,0) -> KV13406 | AM27: Nhân Viên | AN27: Phụ cấp cổng | AO27: 200000 | AQ27: =COUNT(F27:AJ27)-COUNTIF(F27:AJ27,0) -> 30 | AR27: =AK27-AT27-AU27 -> 336 | AS27: =IF(AQ27=30,2,IF(AQ27=29,1,0)) -> 2 | AT27: 24 | AU27: =(SUMIFS(F27:AJ27,F27:AJ27,">12")-(COUNTIF(F27:AJ27,">12")*12)) -> 3 | AV27: =F27+G27 -> 24 | AX27: 400000
B28: 8 | C28: ĐỖ THỊ MINH TÂM | D28: KV10538 | E28: 46082 | F28: NHÂN SỰ SRC CHUYỂN QUA | U28: 12 | V28: 12 | W28: 12 | X28: 12 | Y28: 12 | Z28: 12 | AA28: 12 | AB28: 12 | AC28: 12 | AD28: 12 | AE28: 12 | AF28: 12 | AG28: 12 | AH28: 12 | AI28: 12 | AK28: =SUM(F28:AJ28) -> 180 | AL28: =VLOOKUP(C28,[2]T09.2026!$C$41:$E$65,3,0) -> KV10538 | AM28: Nhân Viên | AN28: Phụ cấp cổng | AO28: 200000 | AQ28: =COUNT(F28:AJ28)-COUNTIF(F28:AJ28,0) -> 15 | AR28: =AK28-AT28-AU28 -> 180 | AS28: =IF(AQ28=30,2,IF(AQ28=29,1,0)) -> 0 | AU28: =(SUMIFS(F28:AJ28,F28:AJ28,">12")-(COUNTIF(F28:AJ28,">12")*12)) -> 0 | AX28: 400000
AK29: =SUM(F29:AJ29) -> 0 | AQ29: =COUNT(F29:AJ29)-COUNTIF(F29:AJ29,0) -> 0 | AR29: =AK29-AT29-AU29 -> 0 | AS29: =IF(AQ29=30,2,IF(AQ29=29,1,0)) -> 0 | AU29: =(SUMIFS(F29:AJ29,F29:AJ29,">12")-(COUNTIF(F29:AJ29,">12")*12)) -> 0 | AV29: =F29+G29 -> 0
B30: C | C30: Cơ động cố định | AK30: =SUM(F30:AJ30) -> 0 | AN30: Ghi chú (ngày đêm) | AQ30: =COUNT(F30:AJ30)-COUNTIF(F30:AJ30,0) -> 0 | AR30: =AK30-AT30-AU30 -> 0 | AS30: =IF(AQ30=30,2,IF(AQ30=29,1,0)) -> 0 | AU30: =(SUMIFS(F30:AJ30,F30:AJ30,">12")-(COUNTIF(F30:AJ30,">12")*12)) -> 0 | AV30: =F30+G30 -> 0
AK31: =SUM(F31:AJ31) -> 0 | AM31: N/V NGHIỆP VỤ | AQ31: =COUNT(F31:AJ31)-COUNTIF(F31:AJ31,0) -> 0 | AR31: =AK31-AT31-AU31 -> 0 | AS31: =IF(AQ31=30,2,IF(AQ31=29,1,0)) -> 0 | AU31: =(SUMIFS(F31:AJ31,F31:AJ31,">12")-(COUNTIF(F31:AJ31,">12")*12)) -> 0 | AV31: =F31+G31 -> 0
B32: D | C32: Đến hỗ trợ Ca Ngày | AK32: =SUM(F32:AJ32) -> 0 | AQ32: =COUNT(F32:AJ32)-COUNTIF(F32:AJ32,0) -> 0 | AR32: =AK32-AT32-AU32 -> 0 | AS32: =IF(AQ32=30,2,IF(AQ32=29,1,0)) -> 0 | AU32: =(SUMIFS(F32:AJ32,F32:AJ32,">12")-(COUNTIF(F32:AJ32,">12")*12)) -> 0 | AV32: =F32+G32 -> 0
B33: 1 | C33: THẨM QUANG TRUNG PHÚC | D33: KV13367 | E33: CĐ | L33: 12 | AJ33: =SUM(U33:AI33) -> 0 | AM33: N/V NGHIỆP VỤ | AQ33: =COUNT(F33:AJ33)-COUNTIF(F33:AJ33,0) -> 1 | AR33: =AK33-AT33-AU33 -> 0 | AS33: =IF(AQ33=30,2,IF(AQ33=29,1,0)) -> 0 | AU33: =(SUMIFS(F33:AJ33,F33:AJ33,">12")-(COUNTIF(F33:AJ33,">12")*12)) -> 0 | AV33: =F33+G33 -> 0
B34: 2 | C34: NGUYỄN HOÀI KHÁNH | D34: KV11416 | S34: 4 | U34: 4 | AA34: 5 | AK34: =SUM(F34:AJ34) -> 13 | AL34: =VLOOKUP(C34,[2]T09.2026!$C$41:$E$65,3,0) -> KV11416 | AM34: N/V NGHIỆP VỤ | AQ34: =COUNT(F34:AJ34)-COUNTIF(F34:AJ34,0) -> 3 | AR34: =AK34-AT34-AU34 -> 13 | AS34: =IF(AQ34=30,2,IF(AQ34=29,1,0)) -> 0 | AU34: =(SUMIFS(F34:AJ34,F34:AJ34,">12")-(COUNTIF(F34:AJ34,">12")*12)) -> 0 | AV34: =F34+G34 -> 0
B35: 3 | C35: NGUYỄN HOÀI THIÊN PHÚC | D35: KV13111 | E35: CĐ | T35: 12 | V35: 12 | AA35: 5 | AJ35: =SUM(U35:AI35) -> 17 | AM35: N/V NGHIỆP VỤ | AQ35: =COUNT(F35:AJ35)-COUNTIF(F35:AJ35,0) -> 4 | AR35: =AK35-AT35-AU35 -> -5 | AS35: =IF(AQ35=30,2,IF(AQ35=29,1,0)) -> 0 | AU35: =(SUMIFS(F35:AJ35,F35:AJ35,">12")-(COUNTIF(F35:AJ35,">12")*12)) -> 5 | AV35: =F35+G35 -> 0
B36: 4 | C36: NGUYỄN PHÚC THÀNH | D36: KV13167 | E36: CĐ | W36: 12 | AJ36: =SUM(U36:AI36) -> 12 | AM36: N/V NGHIỆP VỤ | AQ36: =COUNT(F36:AJ36)-COUNTIF(F36:AJ36,0) -> 2 | AR36: =AK36-AT36-AU36 -> 0 | AS36: =IF(AQ36=30,2,IF(AQ36=29,1,0)) -> 0 | AU36: =(SUMIFS(F36:AJ36,F36:AJ36,">12")-(COUNTIF(F36:AJ36,">12")*12)) -> 0 | AV36: =F36+G36 -> 0
B37: 5 | C37: NGUYỄN VĂN NHÂN | D37: KV13007 | AI37: 12 | AK37: =SUM(F37:AJ37) -> 12 | AL37: =VLOOKUP(C37,[2]T09.2026!$C$41:$E$65,3,0) -> KV13007 | AM37: N/V NGHIỆP VỤ | AQ37: =COUNT(F37:AJ37)-COUNTIF(F37:AJ37,0) -> 1 | AR37: =AK37-AT37-AU37 -> 12 | AS37: =IF(AQ37=30,2,IF(AQ37=29,1,0)) -> 0 | AU37: =(SUMIFS(F37:AJ37,F37:AJ37,">12")-(COUNTIF(F37:AJ37,">12")*12)) -> 0 | AV37: =F37+G37 -> 0
B38: E | C38: Đến hỗ trợ Ca Đêm | AJ38: =SUM(AJ33:AJ37) -> 29 | AQ38: =COUNT(F38:AJ38)-COUNTIF(F38:AJ38,0) -> 1 | AR38: =AK38-AT38-AU38 -> 0 | AS38: =IF(AQ38=30,2,IF(AQ38=29,1,0)) -> 0 | AV38: =F38+G38 -> 0
B39: 1 | C39: BÙI HỮU TRỌNG | D39: KV13334 | S39: 12 | T39: 12 | AK39: =SUM(F39:AJ39) -> 24 | AL39: =VLOOKUP(C39,[2]T09.2026!$C$41:$E$65,3,0) -> KV13334 | AM39: N/V NGHIỆP VỤ | AQ39: =COUNT(F39:AJ39)-COUNTIF(F39:AJ39,0) -> 2 | AR39: =AK39-AT39-AU39 -> 24 | AS39: =IF(AQ39=30,2,IF(AQ39=29,1,0)) -> 0 | AU39: =(SUMIFS(F39:AJ39,F39:AJ39,">12")-(COUNTIF(F39:AJ39,">12")*12)) -> 0 | AV39: =F39+G39 -> 0
B40: 2 | C40: ĐẶNG LƯ PHƯƠNG HIẾU | D40: KV13261 | AA40: 12 | AK40: =SUM(F40:AJ40) -> 12 | AL40: =VLOOKUP(C40,[2]T09.2026!$C$41:$E$65,3,0) -> KV13261 | AM40: N/V NGHIỆP VỤ | AQ40: =COUNT(F40:AJ40)-COUNTIF(F40:AJ40,0) -> 1 | AR40: =AK40-AT40-AU40 -> 12 | AS40: =IF(AQ40=30,2,IF(AQ40=29,1,0)) -> 0 | AU40: =(SUMIFS(F40:AJ40,F40:AJ40,">12")-(COUNTIF(F40:AJ40,">12")*12)) -> 0 | AV40: =F40+G40 -> 0
...

Sheet SRCS
B1: BẢNG CHẤM CÔNG NHÂN VIÊN THÁNG 10/2019 | AM1: - Những cột có dấu (*) là bắt buộc người chấm công phải nhập dữ liệu (nếu có)
B2: ( Từ Ngày 01/10/2019 Đến 31/10/2019 )
C3: Bãi xe:SRCS | AM3: Phần nhập của Quản lý Bãi xe | AQ3: Phần nhập của Phòng HCNS
AM4: (*) | AN4: (*) | AO4: (*) | AP4: (*)
C5: 1 | D5: 1 | E5: 2 | F5: 3 | G5: 4 | H5: 5 | I5: 6 | J5: 7 | K5: 8 | L5: 9 | M5: 10 | N5: 11 | O5: 12 | P5: 13 | Q5: 14 | R5: 15 | S5: 16 | T5: 17 | U5: 18 | V5: 19 | W5: 20 | X5: 21 | Y5: 22 | Z5: 23 | AA5: 24 | AB5: 25 | AC5: 26 | AD5: 27 | AE5: 28 | AF5: 29 | AG5: 30 | AH5: 31 | AI5: 32 | AJ5: 33 | AK5: 34 | AL5: 35 | AM5: 36 | AN5: 37 | AO5: 38 | AP5: 39 | AQ5: 40 | AR5: 41 | AS5: 42 | AT5: 43 | AU5: 44 | AV5: 45 | AW5: 46 | AX5: 47 | AY5: 48
B6: Phần in ra cho Nhân viên ký xác nhận
B7: STT | C7: HỌ VÀ TÊN | D7: Thứ | F7: =TEXT(F8,"ddd") -> T3 | G7: =TEXT(G8,"ddd") -> T4 | H7: =TEXT(H8,"ddd") -> T5 | I7: =TEXT(I8,"ddd") -> T6 | J7: =TEXT(J8,"ddd") -> T7 | K7: =TEXT(K8,"ddd") -> CN | L7: =TEXT(L8,"ddd") -> T2 | M7: =TEXT(M8,"ddd") -> T3 | ... AJ7: =TEXT(AJ8,"ddd") | AL7: NV Ký Xác nhận | AM7: Thông tin Tham chiếu | AQ7: Giờ công (h) | AX7: Đánh giá
D8: Ngày | F8: =DATE(SGP!D7,SGP!D6,1) -> 46266 | G8: =IFERROR(IF(F8+1<=EOMONTH(F8,0),F8+1,""),"") -> 46267 | H8: =IFERROR(IF(G8+1<=EOMONTH(G8,0),G8+1,""),"") -> 46268 | I8: =IFERROR(IF(H8+1<=EOMONTH(H8,0),H8+1,""),"") -> 46269 | J8: =IFERROR(IF(I8+1<=EOMONTH(I8,0),I8+1,""),"") -> 46270 | K8: =IFERROR(IF(J8+1<=EOMONTH(J8,0),J8+1,""),"") -> 46271 | L8: =IFERROR(IF(K8+1<=EOMONTH(K8,0),K8+1,""),"") -> 46272 | M8: =IFERROR(IF(L8+1<=EOMONTH(L8,0),L8+1,""),"") -> 46273 | N8: =IFERROR(IF(M8+1<=EOMONTH(M8,0),M8+1,""),"") -> 46274 | ... AJ8: =IFERROR(IF(AI8+1<=EOMONTH(AI8,0),AI8+1,""),"") | AK8: Tổng giờ Công | AM8: Đối tượng / Chức vụ | AN8: Ghi chú (ghi chú phụ cấp) | AO8: Bãi xe (chỉ ghi khi có NV đến hỗ trợ) | AP8: Ca làm việc | AQ8: Tổng số ngày Làm việc trong tháng | AR8: Giờ công thường 1.0 | AS8: Số ngày tăng ca ngày nghỉ | AT8: Tăng ca ngày 1.3 | AU8: Tăng ca giờ 1.5 | AV8: Tăng ca Lễ 2.0 | AW8: Tăng ca tết 3.0 | AX8: Bãi xe Đánh giá | AY8: P. Nhân sự đánh giá
B9: A | C9: Ca Ngày | D9: MSNV | AN9: 2 cổng | AX9: 0 | AY9: #N/A
B10: 1 | C10: Ng Ng Thượng Hiền | F10: 12 | G10: 12 | H10: 12 | I10: OFF | J10: OFF | K10: 12 | L10: 12 | M10: 12 | N10: 12 | O10: 12 | P10: 12 | Q10: 12 | R10: OFF | S10: 12 | T10: 12 | U10: 12 | V10: 12 | W10: 12 | X10: 12 | Y10: OFF | Z10: 12 | AA10: 12 | AB10: 12 | AC10: 12 | AD10: 12 | AE10: 12 | AF10: OFF | AG10: 12 | AH10: 12 | AI10: 12 | AM10: Đội trưởng | AS10: =IF(AQ10=30,2,IF(AQ10=29,1,0)) -> 0 | AY10: A
B11: 2 | C11: La Bảo Hòa | D11: KV03480 | F11: 12 | G11: OFF | H11: 12 | I11: 12 | J11: 12 | K11: OFF | L11: 12 | M11: 12 | N11: 12 | O11: 14 | P11: 12 | Q11: 12 | R11: 12 | S11: 12 | T11: 12 | U11: 12 | V11: 12 | W11: OFF | X11: 12 | Y11: 12 | Z11: 12 | AA11: 12 | AB11: 12 | AC11: 12 | AD11: 12 | AE11: OFF | AF11: 12 | AG11: 12 | AH11: 12 | AI11: 12 | AK11: =SUM(F11:AJ11) -> 314 | AL11: =VLOOKUP(C11,[2]T09.2026!$C$69:$E$93,3,0) -> KV03480 | AM11: Ca phó | AQ11: =COUNT(F11:AJ11)-COUNTIF(F11:AJ11,0) -> 26 | AR11: =AK11-AT11-AU11 -> 312 | AS11: =IF(AQ11=30,2,IF(AQ11=29,1,0)) -> 0 | AU11: =(SUMIFS(F11:AJ11,F11:AJ11,">12")-(COUNTIF(F11:AJ11,">12")*12)) -> 2 | AV11: 12 | AY11: A
B12: 3 | C12: Nguyễn Xuân Chiêu | D12: KV02925 | F12: 12 | G12: 12 | H12: 12 | I12: 12 | J12: 12 | K12: 12 | L12: 12 | M12: 12 | N12: 12 | O12: 12 | P12: 12 | Q12: 12 | R12: 12 | S12: 12 | T12: OFF | U12: 12 | V12: 12 | W12: 12 | X12: 12 | Y12: 12 | Z12: 12 | AA12: 12 | AB12: 12 | AC12: 12 | AD12: 12 | AE12: 12 | AF12: 12 | AG12: 12 | AH12: 12 | AI12: 12 | AK12: =SUM(F12:AJ12) -> 348 | AL12: =VLOOKUP(C12,[2]T09.2026!$C$69:$E$93,3,0) -> KV02925 | AM12: Nhân Viên Chính Thức | AQ12: =COUNT(F12:AJ12)-COUNTIF(F12:AJ12,0) -> 29 | AR12: =AK12-AT12-AU12 -> 336 | AS12: =IF(AQ12=30,2,IF(AQ12=29,1,0)) -> 1 | AT12: 12 | AU12: =(SUMIFS(F12:AJ12,F12:AJ12,">12")-(COUNTIF(F12:AJ12,">12")*12)) -> 0 | AV12: =F12+G12 -> 24 | AY12: A
B13: 4 | C13: Lê Hiệp | D13: KV03055 | F13: 12 | G13: 12 | H13: 12 | I13: 12 | J13: 12 | K13: 12 | L13: 12 | M13: 12 | N13: 12 | O13: 12 | P13: 12 | Q13: 12 | R13: 12 | S13: 12 | T13: 12 | U13: 12 | V13: 12 | W13: 12 | X13: 12 | Y13: OFF | Z13: 12 | AA13: 12 | AB13: 12 | AC13: 12 | AD13: 12 | AE13: 12 | AF13: 12 | AG13: 12 | AH13: 12 | AI13: 12 | AK13: =SUM(F13:AJ13) -> 348 | AL13: =VLOOKUP(C13,[2]T09.2026!$C$69:$E$93,3,0) -> KV03055 | AM13: Nhân Viên Chính Thức | AQ13: =COUNT(F13:AJ13)-COUNTIF(F13:AJ13,0) -> 29 | AR13: =AK13-AT13-AU13 -> 336 | AS13: =IF(AQ13=30,2,IF(AQ13=29,1,0)) -> 1 | AT13: 12 | AU13: =(SUMIFS(F13:AJ13,F13:AJ13,">12")-(COUNTIF(F13:AJ13,">12")*12)) -> 0 | AV13: =F13+G13 -> 24 | AY13: A
B14: 5 | C14: Hoàng Thị Thu Hồng | D14: KV11590 | F14: 17 | G14: 12 | H14: 7 | I14: 12 | J14: 12 | K14: 12 | L14: 12 | M14: 12 | N14: 12 | O14: 15 | P14: 12 | Q14: 12 | R14: 12 | S14: 12 | T14: 12 | U14: 12 | V14: 12 | W14: 12 | X14: 12 | Y14: 12 | Z14: 12 | AA14: 12 | AB14: 12 | AC14: OFF | AD14: 12 | AE14: 12 | AF14: 12 | AG14: 12 | AH14: 12 | AI14: 12 | AK14: =SUM(F14:AJ14) -> 351 | AL14: =VLOOKUP(C14,[2]T09.2026!$C$69:$E$93,3,0) -> KV11590 | AM14: Nhân Viên Chính Thức | AN14: P/C Cổng vào, 300 | AO14: 300000 | AQ14: =COUNT(F14:AJ14)-COUNTIF(F14:AJ14,0) -> 29 | AR14: =AK14-AT14-AU14 -> 331 | AS14: =IF(AQ14=30,2,IF(AQ14=29,1,0)) -> 1 | AT14: 12 | AU14: =(SUMIFS(F14:AJ14,F14:AJ14,">12")-(COUNTIF(F14:AJ14,">12")*12)) -> 8 | AV14: =F14+G14 -> 29 | AY14: A
B15: 6 | C15: Lê Phước Hữu | D15: KV06173 | F15: 12 | G15: 12 | H15: 12 | I15: 12 | J15: 12 | K15: 12 | L15: 12 | M15: 12 | N15: 12 | O15: 12 | P15: 12 | Q15: 12 | R15: 12 | S15: 12 | T15: 12 | U15: 12 | V15: 12 | W15: 12 | X15: 12 | Y15: 12 | Z15: 12 | AA15: 12 | AB15: 12 | AC15: 12 | AD15: 12 | AE15: 12 | AF15: 12 | AG15: 12 | AH15: 12 | AI15: 12 | AK15: =SUM(F15:AJ15) -> 360 | AL15: =VLOOKUP(C15,[2]T09.2026!$C$69:$E$93,3,0) -> KV06173 | AM15: Nhân Viên Chính Thức | AN15: P/C Cổng vào, 200 | AO15: 200000 | AQ15: =COUNT(F15:AJ15)-COUNTIF(F15:AJ15,0) -> 30 | AR15: =AK15-AT15-AU15 -> 336 | AS15: =IF(AQ15=30,2,IF(AQ15=29,1,0)) -> 2 | AT15: 24 | AU15: =(SUMIFS(F15:AJ15,F15:AJ15,">12")-(COUNTIF(F15:AJ15,">12")*12)) -> 0 | AV15: =F15+G15 -> 24
B16: 7 | C16: Trương Văn Rẻn | D16: KV12312 | F16: HLR | G16: 12 | H16: 12 | I16: 12 | J16: 12 | K16: 12 | L16: 12 | M16: 12 | N16: 12 | O16: 12 | P16: 12 | Q16: 8 | R16: 12 | S16: 12 | T16: 12 | U16: 12 | V16: 12 | W16: 12 | X16: 12 | Y16: 12 | Z16: OFF | AA16: 12 | AB16: 12 | AC16: 12 | AD16: 12 | AE16: 12 | AF16: 12 | AG16: 12 | AH16: 12 | AI16: 12 | AK16: =SUM(F16:AJ16) -> 332 | AL16: =VLOOKUP(C16,[2]T09.2026!$C$69:$E$93,3,0) -> KV12312 | AM16: Nhân Viên Chính Thức | AQ16: =COUNT(F16:AJ16)-COUNTIF(F16:AJ16,0) -> 28 | AR16: =AK16-AT16-AU16 -> 320 | AS16: =IF(AQ16=30,2,IF(AQ16=29,1,0)) -> 0 | AT16: 12 | AU16: =(SUMIFS(F16:AJ16,F16:AJ16,">12")-(COUNTIF(F16:AJ16,">12")*12)) -> 0 | AV16: 12 | AY16: A
B17: 8 | C17: Vưu Hớn Long | D17: KV06862 | F17: 12 | G17: 12 | H17: 12 | I17: 12 | J17: 12 | K17: 12 | L17: 12 | M17: 12 | N17: 12 | O17: Chuyển Bãi | AK17: =SUM(F17:AJ17) -> 108 | AL17: =VLOOKUP(C17,[2]T09.2026!$C$69:$E$93,3,0) -> KV06862 | AQ17: =COUNT(F17:AJ17)-COUNTIF(F17:AJ17,0) -> 9 | AR17: =AK17-AT17-AU17 -> 108 | AS17: =IF(AQ17=30,2,IF(AQ17=29,1,0)) -> 0 | AU17: =(SUMIFS(F17:AJ17,F17:AJ17,">12")-(COUNTIF(F17:AJ17,">12")*12)) -> 0 | AV17: =F17+G17 -> 24 | AY17: A
B18: 9 | C18: Huỳnh Thiên Trinh | D18: KV13456 | E18: 46273 | F18: Nhân Sự Mới | M18: 12 | N18: 12 | O18: 12 | P18: 12 | Q18: 12 | R18: 12 | S18: 12 | T18: 12 | U18: 12 | V18: 12 | W18: 12 | X18: 12 | Y18: 12 | Z18: 12 | AA18: 12 | AB18: 12 | AC18: 12 | AD18: 12 | AE18: 12 | AF18: 12 | AG18: 12 | AH18: 12 | AI18: 12 | AK18: =SUM(F18:AJ18) -> 276 | AL18: =VLOOKUP(C18,[2]T09.2026!$C$69:$E$93,3,0) -> KV13456 | AM18: Nhân Viên Chính Thức | AN18: P/C Cổng ra | AO18: 200000 | AQ18: =COUNT(F18:AJ18)-COUNTIF(F18:AJ18,0) -> 23 | AR18: =AK18-AT18-AU18 -> 276 | AS18: =IF(AQ18=30,2,IF(AQ18=29,1,0)) -> 0 | AU18: =(SUMIFS(F18:AJ18,F18:AJ18,">12")-(COUNTIF(F18:AJ18,">12")*12)) -> 0
B19: 10 | C19: Huỳnh Thanh Toàn | D19: KV12962 | E19: 46102 | F19: Nhân Sự Mới | O19: 12 | P19: 12 | Q19: 12 | R19: 12 | S19: 12 | T19: 12 | U19: 12 | V19: 12 | W19: 12 | X19: 12 | Y19: BỎ VIỆC | AK19: =SUM(F19:AJ19) -> 120 | AL19: =VLOOKUP(C19,[2]T09.2026!$C$69:$E$93,3,0) -> KV12962 | AQ19: =COUNT(F19:AJ19)-COUNTIF(F19:AJ19,0) -> 10 | AR19: =AK19-AT19-AU19 -> 120 | AS19: =IF(AQ19=30,2,IF(AQ19=29,1,0)) -> 0 | AU19: =(SUMIFS(F19:AJ19,F19:AJ19,">12")-(COUNTIF(F19:AJ19,">12")*12)) -> 0 | AY19: A
B20: B | C20: Ca Đêm | D20: MSNV | AQ20: =COUNT(F20:AJ20)-COUNTIF(F20:AJ20,0) -> 0 | AR20: =AK20-AT20-AU20 -> 0 | AS20: =IF(AQ20=30,2,IF(AQ20=29,1,0)) -> 0 | AU20: =(SUMIFS(F20:AJ20,F20:AJ20,">12")-(COUNTIF(F20:AJ20,">12")*12)) -> 0 | AV20: =F20+G20 -> 0 | AY20: A
B21: 1 | C21: Lê Ngọc Hoàng Anh | D21: KV10866 | O21: 13 | P21: 13 | Q21: 13 | R21: 13 | S21: 13 | T21: 13 | U21: 13 | V21: 13 | W21: 12 | X21: 14 | Y21: 12 | Z21: 12 | AA21: 12 | AB21: 14 | AC21: 14 | AD21: 12 | AE21: 14 | AF21: 12 | AG21: 12 | AH21: 12 | AI21: 12 | AK21: =SUM(F21:AJ21) -> 268 | AL21: =VLOOKUP(C21,[2]T09.2026!$C$69:$E$93,3,0) -> KV10866 | AQ21: =COUNT(F21:AJ21)-COUNTIF(F21:AJ21,0) -> 21 | AR21: =AK21-AT21-AU21 -> 228 | AS21: =IF(AQ21=30,2,IF(AQ21=29,1,0)) -> 0 | AT21: 24 | AU21: =(SUMIFS(F21:AJ21,F21:AJ21,">12")-(COUNTIF(F21:AJ21,">12")*12)) -> 16 | AV21: =F21+G21 -> 0 | AX21: 400000 | AY21: A
B22: 2 | C22: Nguyễn Thanh Hiền | D22: KV02333 | F22: 12 | G22: 16 | H22: 12 | I22: 12 | J22: 12 | K22: 12 | L22: 12 | M22: 12 | N22: 12 | O22: 12 | P22: 12 | Q22: 12 | R22: 12 | S22: 12 | T22: 12 | U22: 12 | V22: 12 | W22: 12 | X22: 12 | Y22: 12 | Z22: 12 | AA22: 12 | AB22: 12 | AC22: 12 | AD22: 12 | AE22: 12 | AF22: 12 | AG22: 12 | AH22: 12 | AI22: 12 | AK22: =SUM(F22:AJ22) -> 364 | AL22: =VLOOKUP(C22,[2]T09.2026!$C$69:$E$93,3,0) -> KV02333 | AM22: MO | AN22: P/C Cổng vào, 200 | AO22: 200000 | AQ22: =COUNT(F22:AJ22)-COUNTIF(F22:AJ22,0) -> 30 | AR22: =AK22-AT22-AU22 -> 336 | AS22: =IF(AQ22=30,2,IF(AQ22=29,1,0)) -> 2 | AT22: 24 | AU22: =(SUMIFS(F22:AJ22,F22:AJ22,">12")-(COUNTIF(F22:AJ22,">12")*12)) -> 4 | AV22: =F22+G22 -> 28 | AX22: 400000 | AY22: A
B23: 3 | C23: Nguyễn Duy Dũng | D23: KV05891 | F23: 12 | G23: 12 | H23: 12 | I23: 12 | J23: 12 | K23: 12 | L23: 12 | M23: 12 | N23: 12 | O23: 12 | P23: 12 | Q23: 12 | R23: 12 | S23: 12 | T23: 12 | U23: 12 | V23: 12 | W23: 12 | X23: 12 | Y23: 12 | Z23: 12 | AA23: 12 | AB23: 12 | AC23: 12 | AD23: 12 | AE23: 12 | AF23: 12 | AG23: 12 | AH23: 12 | AI23: 12 | AK23: =SUM(F23:AJ23) -> 360 | AL23: =VLOOKUP(C23,[2]T09.2026!$C$69:$E$93,3,0) -> KV05891 | AM23: Nhân Viên Chính Thức | AQ23: =COUNT(F23:AJ23)-COUNTIF(F23:AJ23,0) -> 30 | AR23: =AK23-AT23-AU23 -> 336 | AS23: =IF(AQ23=30,2,IF(AQ23=29,1,0)) -> 2 | AT23: 24 | AU23: =(SUMIFS(F23:AJ23,F23:AJ23,">12")-(COUNTIF(F23:AJ23,">12")*12)) -> 0 | AV23: =F23+G23 -> 24 | AX23: 400000 | AY23: A
B24: 4 | C24: Nguyễn Văn Phước | D24: KV11865 | F24: 16 | G24: 16 | H24: 10 | I24: 17 | J24: 17 | K24: 12 | L24: 12 | M24: 12 | N24: 12 | O24: 12 | P24: 12 | Q24: 12 | R24: 12 | S24: 12 | T24: 12 | U24: 12 | V24: 12 | W24: 12 | X24: SA THẢI | AK24: =SUM(F24:AJ24) -> 232 | AL24: =VLOOKUP(C24,[2]T09.2026!$C$69:$E$93,3,0) -> KV11865 | AM24: Nhân Viên Chính Thức | AQ24: =COUNT(F24:AJ24)-COUNTIF(F24:AJ24,0) -> 18 | AR24: =AK24-AT24-AU24 -> 214 | AS24: =IF(AQ24=30,2,IF(AQ24=29,1,0)) -> 0 | AU24: =(SUMIFS(F24:AJ24,F24:AJ24,">12")-(COUNTIF(F24:AJ24,">12")*12)) -> 18 | AV24: =F24+G24 -> 32 | AX24: 400000 | AY24: A
B25: 5 | C25: Trần Văn Vân | D25: KV12982 | F25: 12 | G25: 12 | H25: 12 | I25: 12 | J25: 12 | K25: 12 | L25: 12 | M25: 12 | N25: 12 | O25: 12 | P25: 12 | Q25: 12 | R25: 12 | S25: 12 | T25: 12 | U25: 12 | V25: 12 | W25: 12 | X25: 12 | Y25: 12 | Z25: 12 | AA25: 12 | AB25: 12 | AC25: 12 | AD25: 12 | AE25: 12 | AF25: 12 | AG25: 12 | AH25: 12 | AI25: 12 | AK25: =SUM(F25:AJ25) -> 360 | AL25: =VLOOKUP(C25,[2]T09.2026!$C$69:$E$93,3,0) -> KV12982 | AM25: Nhân Viên Chính Thức | AQ25: =COUNT(F25:AJ25)-COUNTIF(F25:AJ25,0) -> 30 | AR25: =AK25-AT25-AU25 -> 336 | AS25: =IF(AQ25=30,2,IF(AQ25=29,1,0)) -> 2 | AT25: 24 | AU25: =(SUMIFS(F25:AJ25,F25:AJ25,">12")-(COUNTIF(F25:AJ25,">12")*12)) -> 0 | AV25: =F25+G25 -> 24 | AX25: 400000 | AY25: A
B26: 6 | C26: Nguyễn Việt Linh | D26: KV11379 | F26: OFF | G26: 12 | H26: 12 | I26: 12 | J26: 12 | K26: 12 | L26: 12 | M26: 12 | N26: 12 | O26: 12 | P26: OFF | Q26: OFF | R26: ht | S26: 12 | T26: ht | U26: ht | V26: ht | W26: 12 | X26: 9 | Y26: 10 | Z26: OFF | AA26: 12 | AB26: 12 | AC26: 12 | AD26: 12 | AE26: 12 | AF26: 12 | AG26: 12 | AH26: 12 | AI26: 12 | AK26: =SUM(F26:AJ26) -> 259 | AL26: =VLOOKUP(C26,[2]T09.2026!$C$69:$E$93,3,0) -> KV11379 | AM26: Nhân Viên Chính Thức | AN26: P/C Cổng vào, 300 | AO26: 300000 | AQ26: =COUNT(F26:AJ26)-COUNTIF(F26:AJ26,0) -> 22 | AR26: =AK26-AT26-AU26 -> 259 | AS26: =IF(AQ26=30,2,IF(AQ26=29,1,0)) -> 0 | AU26: =(SUMIFS(F26:AJ26,F26:AJ26,">12")-(COUNTIF(F26:AJ26,">12")*12)) -> 0 | AV26: 12 | AX26: 400000 | AY26: A
B27: 7 | C27: Nguyễn Thanh Tâm | D27: KV13396 | F27: 12 | G27: 12 | H27: OFF | I27: 12 | J27: 12 | K27: 12 | L27: 12 | M27: 12 | N27: 12 | O27: OFF | P27: 12 | Q27: 12 | R27: 12 | S27: 12 | T27: 12 | U27: 12 | V27: 12 | W27: OFF | X27: 12 | Y27: 12 | Z27: 12 | AA27: 12 | AB27: NGHỈ VIỆC | AK27: =SUM(F27:AJ27) -> 228 | AL27: =VLOOKUP(C27,[2]T09.2026!$C$69:$E$93,3,0) -> KV13396 | AQ27: =COUNT(F27:AJ27)-COUNTIF(F27:AJ27,0) -> 19 | AR27: =AK27-AT27-AU27 -> 228 | AS27: =IF(AQ27=30,2,IF(AQ27=29,1,0)) -> 0 | AU27: =(SUMIFS(F27:AJ27,F27:AJ27,">12")-(COUNTIF(F27:AJ27,">12")*12)) -> 0 | AV27: =F27+G27 -> 24 | AX27: 400000
B28: 8 | C28: Lê Ngọc Hiếu | D28: KV13414 | F28: 12 | G28: 12 | H28: 12 | I28: OFF | J28: 12 | K28: 12 | L28: 12 | M28: 12 | N28: 12 | O28: 12 | P28: 12 | Q28: 12 | R28: 12 | S28: 12 | T28: 12 | U28: 12 | V28: 12 | W28: 12 | X28: 12 | Y28: 12 | Z28: 12 | AA28: 12 | AB28: 12 | AC28: 12 | AD28: OFF | AE28: 12 | AF28: 12 | AG28: 12 | AH28: 12 | AI28: 12 | AK28: =SUM(F28:AJ28) -> 336 | AL28: =VLOOKUP(C28,[2]T09.2026!$C$69:$E$93,3,0) -> KV13414 | AN28: PC CỔNG RA | AO28: 200000 | AQ28: =COUNT(F28:AJ28)-COUNTIF(F28:AJ28,0) -> 28 | AR28: =AK28-AT28-AU28 -> 336 | AS28: =IF(AQ28=30,2,IF(AQ28=29,1,0)) -> 0 | AU28: =(SUMIFS(F28:AJ28,F28:AJ28,">12")-(COUNTIF(F28:AJ28,">12")*12)) -> 0 | AV28: =F28+G28 -> 24 | AX28: 400000
B29: 9 | C29: Võ Nhựt Phát | D29: KV11914 | E29: 45726 | F29: Nhân Sự Mới | AB29: 12 | AC29: 12 | AD29: 12 | AE29: 12 | AF29: 12 | AG29: 12 | AH29: 12 | AI29: 12 | AK29: =SUM(F29:AJ29) -> 96 | AL29: =VLOOKUP(C29,[2]T09.2026!$C$69:$E$93,3,0) -> KV11914 | AQ29: =COUNT(F29:AJ29)-COUNTIF(F29:AJ29,0) -> 8 | AR29: =AK29-AT29-AU29 -> 72 | AS29: =IF(AQ29=30,2,IF(AQ29=29,1,0)) -> 0 | AT29: 24 | AU29: =(SUMIFS(F29:AJ29,F29:AJ29,">12")-(COUNTIF(F29:AJ29,">12")*12)) -> 0 | AX29: 400000
C31: Cơ Động | AQ31: =COUNT(F31:AJ31)-COUNTIF(F31:AJ31,0) -> 0 | AR31: =AK31-AT31-AU31 -> 0 | AS31: =IF(AQ31=30,2,IF(AQ31=29,1,0)) -> 0 | AU31: =(SUMIFS(F31:AJ31,F31:AJ31,">12")-(COUNTIF(F31:AJ31,">12")*12)) -> 0 | AV31: =F31+G31 -> 0
C32: Bùi Hữu Trọng | D32: KV13334 | H32: 12 | AK32: =SUM(F32:AJ32) -> 12 | AL32: =VLOOKUP(C32,[2]T09.2026!$C$69:$E$93,3,0) -> KV13334 | AQ32: =COUNT(F32:AJ32)-COUNTIF(F32:AJ32,0) -> 1 | AR32: =AK32-AT32-AU32 -> 12 | AS32: =IF(AQ32=30,2,IF(AQ32=29,1,0)) -> 0 | AU32: =(SUMIFS(F32:AJ32,F32:AJ32,">12")-(COUNTIF(F32:AJ32,">12")*12)) -> 0 | AV32: =F32+G32 -> 0
C33: Kiều Anh Duy | D33: KV12858 | AC33: 12 | AK33: =SUM(F33:AJ33) -> 12 | AL33: =VLOOKUP(C33,[2]T09.2026!$C$69:$E$93,3,0) -> KV12858 | AQ33: =COUNT(F33:AJ33)-COUNTIF(F33:AJ33,0) -> 1 | AR33: =AK33-AT33-AU33 -> 12 | AS33: =IF(AQ33=30,2,IF(AQ33=29,1,0)) -> 0 | AU33: =(SUMIFS(F33:AJ33,F33:AJ33,">12")-(COUNTIF(F33:AJ33,">12")*12)) -> 0 | AV33: =F33+G33 -> 0
C34: Nguyễn Thành Anh Tuấn | D34: KV13404 | I34: 12 | AK34: =SUM(F34:AJ34) -> 12 | AQ34: =COUNT(F34:AJ34)-COUNTIF(F34:AJ34,0) -> 1 | AR34: =AK34-AT34-AU34 -> 12 | AS34: =IF(AQ34=30,2,IF(AQ34=29,1,0)) -> 0 | AU34: =(SUMIFS(F34:AJ34,F34:AJ34,">12")-(COUNTIF(F34:AJ34,">12")*12)) -> 0 | AV34: =F34+G34 -> 0
B35: C | C35: HT VT Ca Ngày | AK35: =SUM(F35:AJ35) -> 0 | AQ35: =COUNT(F35:AJ35)-COUNTIF(F35:AJ35,0) -> 0 | AR35: =AK35-AT35-AU35 -> 0 | AS35: =IF(AQ35=30,2,IF(AQ35=29,1,0)) -> 0 | AU35: =(SUMIFS(F35:AJ35,F35:AJ35,">12")-(COUNTIF(F35:AJ35,">12")*12)) -> 0 | AV35: =F35+G35 -> 0
B36: D | C36: Lương Thành Phát | D36: KV6096 | G36: X | I36: X | R36: X | S36: X | T36: X | U36: X | AC36: X | AD36: X | AE36: X | AF36: X | AG36: X | AH36: X | AI36: X | AK36: =SUM(F36:AJ36) -> 0 | AL36: 13 ngày | AQ36: =COUNT(F36:AJ36)-COUNTIF(F36:AJ36,0) -> 0 | AR36: =AK36-AT36-AU36 -> 0 | AS36: =IF(AQ36=30,2,IF(AQ36=29,1,0)) -> 0 | AU36: =(SUMIFS(F36:AJ36,F36:AJ36,">12")-(COUNTIF(F36:AJ36,">12")*12)) -> 0
B37: 1 | C37: Đoàn Hoàn Hùng | F37: X | G37: X | H37: X | I37: X | J37: X | K37: X | L37: X | M37: X | N37: X | O37: X | P37: X | Q37: X | AK37: =SUM(F37:AJ37) -> 0 | AL37: 12 ngày | AQ37: =COUNT(F37:AJ37)-COUNTIF(F37:AJ37,0) -> 0 | AR37: =AK37-AT37-AU37 -> 0 | AS37: =IF(AQ37=30,2,IF(AQ37=29,1,0)) -> 0 | AU37: =(SUMIFS(F37:AJ37,F37:AJ37,">12")-(COUNTIF(F37:AJ37,">12")*12)) -> 0
B38: 2 | C38: Đặng Đăng Đông | D38: KV12095 | F38: X | G38: X | H38: X | I38: X | J38: X | K38: X | L38: X | M38: X | N38: X | O38: X | P38: X | Q38: X | R38: X | T38: X | U38: X | V38: X | W38: X | X38: X | Y38: X | Z38: X | AA38: X | AB38: X | AC38: X | AD38: X | AE38: X | AF38: X | AK38: =SUM(F38:AJ38) -> 0 | AL38: 26 ngày | AQ38: =COUNT(F38:AJ38)-COUNTIF(F38:AJ38,0) -> 0 | AR38: =AK38-AT38-AU38 -> 0 | AS38: =IF(AQ38=30,2,IF(AQ38=29,1,0)) -> 0 | AU38: =(SUMIFS(F38:AJ38,F38:AJ38,">12")-(COUNTIF(F38:AJ38,">12")*12)) -> 0
B39: D | C39: HT VT Ca Dêm | AQ39: =COUNT(F39:AJ39)-COUNTIF(F39:AJ39,0) -> 0 | AR39: =AK39-AT39-AU39 -> 0 | AS39: =IF(AQ39=30,2,IF(AQ39=29,1,0)) -> 0 | AU39: =(SUMIFS(F39:AJ39,F39:AJ39,">12")-(COUNTIF(F39:AJ39,">12")*12)) -> 0 | AV39: =F39+G39 -> 0
B40: E | C40: Đi hỗ trợ | AQ40: =COUNT(F40:AJ40)-COUNTIF(F40:AJ40,0) -> 0 | AR40: =AK40-AT40-AU40 -> 0 | AS40: =IF(AQ40=31,2,IF(AQ40=30,1,0)) -> 0 | AU40: =(SUMIFS(F40:AJ40,F40:AJ40,">12")-(COUNTIF(F40:AJ40,">12")*12)) -> 0
B41: 1 | C41: Nguyễn thanh hiền | D41: kv2333 | F41: X | G41: X | H41: X | I41: X | J41: X | K41: X | M41: X | N41: X | O41: X | P41: X | Q41: X | R41: X | S41: X | U41: X | V41: X | AQ41: =COUNT(F41:AJ41)-COUNTIF(F41:AJ41,0) -> 0 | AR41: =AK41-AT41-AU41 -> 0 | AS41: =IF(AQ41=31,2,IF(AQ41=30,1,0)) -> 0 | AU41: =(SUMIFS(F41:AJ41,F41:AJ41,">12")-(COUNTIF(F41:AJ41,">12")*12)) -> 0
...

Sheet DIL
B1: BẢNG CHẤM CÔNG NHÂN VIÊN THÁNG 09 NĂM2019 | AM1: - Những cột có dấu (*) là bắt buộc người chấm công phải nhập dữ liệu (nếu có)
B2: ( Từ Ngày 01/9/2019 Đến 30/9/2019 )
C3: Bãi xe: DIL | AM3: Phần nhập của Quản lý Bãi xe | AQ3: Phần nhập của Phòng HCNS
AM4: (*) | AN4: (*) | AO4: (*) | AP4: (*)
C5: 1 | D5: 1 | E5: 2 | F5: 3 | G5: 4 | H5: 5 | I5: 6 | J5: 7 | K5: 8 | L5: 9 | M5: 10 | N5: 11 | O5: 12 | P5: 13 | Q5: 14 | R5: 15 | S5: 16 | T5: 17 | U5: 18 | V5: 19 | W5: 20 | X5: 21 | Y5: 22 | Z5: 23 | AA5: 24 | AB5: 25 | AC5: 26 | AD5: 27 | AE5: 28 | AF5: 29 | AG5: 30 | AH5: 31 | AI5: 32 | AJ5: 33 | AK5: 34 | AL5: 35 | AM5: 36 | AN5: 37 | AO5: 38 | AP5: 39 | AQ5: 40 | AR5: 41 | AS5: 42 | AT5: 43 | AU5: 44 | AV5: 45 | AW5: 46 | AX5: 47 | AY5: 48
B6: Phần in ra cho Nhân viên ký xác nhận
B7: STT | C7: HỌ VÀ TÊN | D7: Thứ | F7: =TEXT(F8,"ddd") -> T3 | G7: =TEXT(G8,"ddd") -> T4 | H7: =TEXT(H8,"ddd") -> T5 | I7: =TEXT(I8,"ddd") -> T6 | J7: =TEXT(J8,"ddd") -> T7 | K7: =TEXT(K8,"ddd") -> CN | L7: =TEXT(L8,"ddd") -> T2 | M7: =TEXT(M8,"ddd") -> T3 | ... AJ7: =TEXT(AJ8,"ddd") | AL7: NV Ký Xác nhận | AM7: Thông tin Tham chiếu | AQ7: Giờ công (h) | AX7: Đánh giá
D8: Ngày | F8: =DATE(SGP!D7,SGP!D6,1) -> 46266 | G8: =IFERROR(IF(F8+1<=EOMONTH(F8,0),F8+1,""),"") -> 46267 | H8: =IFERROR(IF(G8+1<=EOMONTH(G8,0),G8+1,""),"") -> 46268 | I8: =IFERROR(IF(H8+1<=EOMONTH(H8,0),H8+1,""),"") -> 46269 | J8: =IFERROR(IF(I8+1<=EOMONTH(I8,0),I8+1,""),"") -> 46270 | K8: =IFERROR(IF(J8+1<=EOMONTH(J8,0),J8+1,""),"") -> 46271 | L8: =IFERROR(IF(K8+1<=EOMONTH(K8,0),K8+1,""),"") -> 46272 | M8: =IFERROR(IF(L8+1<=EOMONTH(L8,0),L8+1,""),"") -> 46273 | N8: =IFERROR(IF(M8+1<=EOMONTH(M8,0),M8+1,""),"") -> 46274 | ... AJ8: =IFERROR(IF(AI8+1<=EOMONTH(AI8,0),AI8+1,""),"") | AK8: Tổng giờ Công | AM8: Đối tượng / Chức vụ | AN8: Ghi chú (ghi chú phụ cấp) | AO8: Bãi xe (chỉ ghi khi có NV đến hỗ trợ) | AP8: Ca làm việc | AQ8: Tổng số ngày Làm việc trong tháng | AR8: Giờ công thường 1.0 | AS8: Số ngày tăng ca ngày nghỉ | AT8: Tăng ca ngày 1.3 | AU8: Tăng ca giờ 1.5 | AV8: Tăng ca Lễ 2.0 | AW8: Tăng ca tết 3.0 | AX8: Bãi xe Đánh giá | AY8: P. Nhân sự đánh giá
